Workbook
Name DB_Annee: 'TABLEAU DE BORD'!$C$7
Name DB_Domaine: 'TABLEAU DE BORD'!$K$7
Name DB_Donateur: 'TABLEAU DE BORD'!$L$12
Name DB_Mois: 'TABLEAU DE BORD'!$G$7
Name DB_Projet: 'TABLEAU DE BORD'!$H$12
Name DB_Zone: 'TABLEAU DE BORD'!$P$12
Name Liste_ActivitesID: OFFSET(ACTIVITES!$A$56,0,0,MAX(1,COUNTIF(ACTIVITES!$G$56:$G$105,"<>")),1)
Name Liste_ActivitesIDProjets: OFFSET(PROJETS!$A$56,0,0,MAX(1,COUNTIF(PROJETS!$C$56:$C$95,"<>")),1)
Name Liste_Annees: tbl_Annees[Annee]
Name Liste_AnneesFiltre: PARAMETRES!$B$738:$B$749
Name Liste_BudgetLignesID: OFFSET(BUDGET!$A$28,0,0,MAX(1,COUNTIF(BUDGET!$U$28:$U$67,"<>")),1)
Name Liste_CategoriesBeneficiaires: tbl_CategoriesBeneficiaires[Libelle]
Name Liste_CategoriesDepenses: tbl_CategoriesDepenses[Libelle]
Name Liste_Departements: PARAMETRES!$D$536:$D$586
Name Liste_DepensesID: OFFSET(DEPENSES!$A$119,0,0,MAX(1,COUNTIF(DEPENSES!$V$119:$V$168,"<>")),1)
Name Liste_Domaines: tbl_Domaines[Libelle]
Name Liste_DonateursDemandesID: DONATEURS!$A$308:$A$367
Name Liste_DonateursID: OFFSET(DONATEURS!$A$56,0,0,MAX(1,COUNTIF(DONATEURS!$B$56:$B$205,"<>")),1)
Name Liste_DonateursOpportunitesID: DONATEURS!$A$244:$A$303
Name Liste_Fonctions: tbl_Fonctions[Libelle]
Name Liste_FrequencesPaiement: PARAMETRES!$B$714:$B$718
Name Liste_ModesPaiement: tbl_ModesPaiement[Libelle]
Name Liste_Mois: tbl_Mois[Mois]
Name Liste_MotifsDepart: PARAMETRES!$B$703:$B$709
Name Liste_NiveauxCompetence: PARAMETRES!$B$695:$B$698
Name Liste_NiveauxHierarchiques: PARAMETRES!$B$666:$B$671
Name Liste_NiveauxPriorite: tbl_NiveauxPriorite[Libelle]
Name Liste_NiveauxRisque: tbl_NiveauxRisque[Libelle]
Name Liste_PartenairesID: PARTENAIRES!$A$56:$A$115
Name Liste_RecettesID: RECETTES!$A$39:$A$88
Name Liste_RHID: OFFSET('RESSOURCES HUMAINES'!$A$27,0,0,MAX(1,COUNTIF('RESSOURCES HUMAINES'!$B$27:$B$76,"<>")),1)
Name Liste_ServicesRH: PARAMETRES!$B$651:$B$662
Name Liste_Sexe: tbl_Sexe[Libelle]
Name Liste_SourcesFinancement: tbl_SourcesFinancement[Libelle]
Name Liste_StatutsActivites: tbl_StatutsActivites[Libelle]
Name Liste_StatutsBudget: tbl_StatutsBudget[Libelle]
Name Liste_StatutsConge: PARAMETRES!$B$686:$B$691
Name Liste_StatutsDocuments: tbl_StatutsDocuments[Libelle]
Name Liste_StatutsGeneraux: tbl_StatutsGeneraux[Libelle]
Name Liste_StatutsProjets: tbl_StatutsProjets[Libelle]
Name Liste_StatutsRecettes: tbl_StatutsRecettes[Libelle]
Name Liste_StatutsRH: PARAMETRES!$B$640:$B$646
Name Liste_StatutsRisques: tbl_StatutsRisques[Libelle]
Name Liste_TranchesAge: tbl_TranchesAge[Libelle]
Name Liste_Trimestres: tbl_Trimestres[Code]
Name Liste_TypesActivites: tbl_TypesActivites[Libelle]
Name Liste_TypesBudget: tbl_TypesBudget[Libelle]
Name Liste_TypesConge: PARAMETRES!$B$676:$B$681
Name Liste_TypesContrats: tbl_TypesContrats[Libelle]
Name Liste_TypesDocuments: tbl_TypesDocuments[Libelle]
Name Liste_TypesDocumentsRH: PARAMETRES!$B$723:$B$734
Name Liste_TypesDonateurs: tbl_TypesDonateurs[Libelle]
Name Liste_TypesFinancement: tbl_TypesFinancement[Libelle]
Name Liste_TypesImmobilisations: tbl_TypesImmobilisations[Libelle]
Name Liste_TypesPartenaires: tbl_TypesPartenaires[Libelle]
Name Liste_TypesProjets: tbl_TypesProjets[Libelle]
Name Liste_TypesRecettes: tbl_TypesRecettes[Libelle]
Name Liste_UnitesMesure: tbl_UnitesMesure[Libelle]
Name Liste_ZonesGeo: PARAMETRES!$J$536:$J$586
Name Seuil_Depassement: PARAMETRES!$C$622

Sheet TABLEAU DE BORD
B1: O.N.G BK | TABLEAU DE BORD DE PILOTAGE | Y1: O.N.G BK | TABLEAU DE BORD DE PILOTAGE | AV1: O.N.G BK | TABLEAU DE BORD DE PILOTAGE
AA3: 2025 | AB3: Février | AC3: Formation professionnelle | AE3: Mars | AF3: =IF($C$7="Toutes les années",IF($K$7="Tous",SUMIFS(RECETTES!$AB$39:$AB$88,RECETTES!$X$39:$X$88,AE3),SUMIFS(RECETTES!$AB$39:$AB$88,RECETTES!$X$39:$X$88,AE3,RECETTES!$J$39:$J$88,$K$7)),IF($K$7="Tous",SUMIFS(RECETTES!$AB$39:$AB$88,RECETTES!$V$39:$V$88,$C$7,RECETTES!$X$39:$X$88,AE3),SUMIFS(RECETTES!$AB$39:$AB$88,RECETTES!$V$39:$V$88,$C$7,RECETTES!$X$39:$X$88,AE3,RECETTES!$J$39:$J$88,$K$7))) -> 0 | AG3: =IF($C$7="Toutes les années",IF($K$7="Tous",SUMIFS(DEPENSES!$AG$119:$AG$168,DEPENSES!$BO$119:$BO$168,AE3),SUMIFS(DEPENSES!$AG$119:$AG$168,DEPENSES!$BO$119:$BO$168,AE3,DEPENSES!$G$119:$G$168,$K$7)),IF($K$7="Tous",SUMIFS(DEPENSES!$AG$119:$AG$168,DEPENSES!$BM$119:$BM$168,$C$7,DEPENSES!$BO$119:$BO$168,AE3),SUMIFS(DEPENSES!$AG$119:$AG$168,DEPENSES!$BM$119:$BM$168,$C$7,DEPENSES!$BO$119:$BO$168,AE3,DEPENSES!$G$119:$G$168,$K$7))) -> 0 | AI3: Terminé | AJ3: =IF($C$7="Toutes les années",IF($K$7="Tous",COUNTIFS(PROJETS!$A$56:$A$95,"PROJ*",PROJETS!$AD$56:$AD$95,"Termine"),COUNTIFS(PROJETS!$A$56:$A$95,"PROJ*",PROJETS!$J$56:$J$95,$K$7,PROJETS!$AD$56:$AD$95,"Termine")),IF($K$7="Tous",COUNTIFS(PROJETS!$A$56:$A$95,"PROJ*",PROJETS!$AD$56:$AD$95,"Termine",PROJETS!$X$56:$X$95,">="&DATE($C$7,1,1),PROJETS!$X$56:$X$95,"<"&DATE($C$7+1,1,1)),COUNTIFS(PROJETS!$A$56:$A$95,"PROJ*",PROJETS!$J$56:$J$95,$K$7,PROJETS!$AD$56:$AD$95,"Termine",PROJETS!$X$56:$X$95,">="&DATE($C$7,1,1),PROJETS!$X$56:$X$95,"<"&DATE($C$7+1,1,1)))) -> 0 | AO3: Réalisée | AP3: =IF($C$7="Toutes les années",IF($K$7="Tous",COUNTIFS(ACTIVITES!$A$56:$A$105,"ACT*",ACTIVITES!$Z$56:$Z$105,"Realisee"),COUNTIFS(ACTIVITES!$A$56:$A$105,"ACT*",ACTIVITES!$K$56:$K$105,$K$7,ACTIVITES!$Z$56:$Z$105,"Realisee")),IF($K$7="Tous",COUNTIFS(ACTIVITES!$A$56:$A$105,"ACT*",ACTIVITES!$S$56:$S$105,$C$7,ACTIVITES!$Z$56:$Z$105,"Realisee"),COUNTIFS(ACTIVITES!$A$56:$A$105,"ACT*",ACTIVITES!$K$56:$K$105,$K$7,ACTIVITES!$S$56:$S$105,$C$7,ACTIVITES!$Z$56:$Z$105,"Realisee"))) -> 0 | AR3: 2025 | AS3: =COUNTIFS(PROJETS!$A$56:$A$95,"PROJ*",PROJETS!$X$56:$X$95,">="&DATE(AR3,1,1),PROJETS!$X$56:$X$95,"<"&DATE(AR3+1,1,1)) -> 0 | AT3: =COUNTIFS(BENEFICIAIRES!$A$56:$A$115,"BEN*",BENEFICIAIRES!$BB$56:$BB$115,">="&DATE(AR3,1,1),BENEFICIAIRES!$BB$56:$BB$115,"<"&DATE(AR3+1,1,1)) -> 0 | AU3: =SUMIFS(RECETTES!$AB$39:$AB$88,RECETTES!$V$39:$V$88,AR3) -> 0 | AV3: =SUMIFS(DEPENSES!$AG$119:$AG$168,DEPENSES!$BM$119:$BM$168,AR3) -> 0 | AW3: =COUNTIFS(ACTIVITES!$A$56:$A$105,"ACT*",ACTIVITES!$S$56:$S$105,AR3,ACTIVITES!$Z$56:$Z$105,"Realisee") -> 0 | AX3: =AR2 -> 0 | AY3: =AS2 -> 0 | AZ3: Février | BA3: =IF($C$7="Toutes les années",SUMIFS(RECETTES!$AB$39:$AB$88,RECETTES!$V$39:$V$88,2026,RECETTES!$W$39:$W$88,2),SUMIFS(RECETTES!$AB$39:$AB$88,RECETTES!$V$39:$V$88,$C$7,RECETTES!$W$39:$W$88,2)) -> 0 | BB3: =IF($C$7="Toutes les années",SUMIFS(DEPENSES!$AG$119:$AG$168,DEPENSES!$BM$119:$BM$168,2026,DEPENSES!$BN$119:$BN$168,2),SUMIFS(DEPENSES!$AG$119:$AG$168,DEPENSES!$BM$119:$BM$168,$C$7,DEPENSES!$BN$119:$BN$168,2)) -> 0 | BC3: =BA3-BB3 -> 0 | BE3: =AE2 -> 0 | BF3: =AF2 -> 0 | BG3: =AG2 -> 0 | BI3: =AI2 -> 0 | BJ3: =AJ2 -> 0 | BL3: =AL2 -> 0 | BM3: =AM2 -> 0 | BO3: =AO2 -> 0 | BP3: =AP2 -> 0
AA4: 2026 | AB4: Mars | AC4: Entrepreneuriat | AE4: Avril | AF4: =IF($C$7="Toutes les années",IF($K$7="Tous",SUMIFS(RECETTES!$AB$39:$AB$88,RECETTES!$X$39:$X$88,AE4),SUMIFS(RECETTES!$AB$39:$AB$88,RECETTES!$X$39:$X$88,AE4,RECETTES!$J$39:$J$88,$K$7)),IF($K$7="Tous",SUMIFS(RECETTES!$AB$39:$AB$88,RECETTES!$V$39:$V$88,$C$7,RECETTES!$X$39:$X$88,AE4),SUMIFS(RECETTES!$AB$39:$AB$88,RECETTES!$V$39:$V$88,$C$7,RECETTES!$X$39:$X$88,AE4,RECETTES!$J$39:$J$88,$K$7))) -> 0 | AG4: =IF($C$7="Toutes les années",IF($K$7="Tous",SUMIFS(DEPENSES!$AG$119:$AG$168,DEPENSES!$BO$119:$BO$168,AE4),SUMIFS(DEPENSES!$AG$119:$AG$168,DEPENSES!$BO$119:$BO$168,AE4,DEPENSES!$G$119:$G$168,$K$7)),IF($K$7="Tous",SUMIFS(DEPENSES!$AG$119:$AG$168,DEPENSES!$BM$119:$BM$168,$C$7,DEPENSES!$BO$119:$BO$168,AE4),SUMIFS(DEPENSES!$AG$119:$AG$168,DEPENSES!$BM$119:$BM$168,$C$7,DEPENSES!$BO$119:$BO$168,AE4,DEPENSES!$G$119:$G$168,$K$7))) -> 0 | AI4: Suspendu | AJ4: =IF($C$7="Toutes les années",IF($K$7="Tous",COUNTIFS(PROJETS!$A$56:$A$95,"PROJ*",PROJETS!$AD$56:$AD$95,"Suspendu"),COUNTIFS(PROJETS!$A$56:$A$95,"PROJ*",PROJETS!$J$56:$J$95,$K$7,PROJETS!$AD$56:$AD$95,"Suspendu")),IF($K$7="Tous",COUNTIFS(PROJETS!$A$56:$A$95,"PROJ*",PROJETS!$AD$56:$AD$95,"Suspendu",PROJETS!$X$56:$X$95,">="&DATE($C$7,1,1),PROJETS!$X$56:$X$95,"<"&DATE($C$7+1,1,1)),COUNTIFS(PROJETS!$A$56:$A$95,"PROJ*",PROJETS!$J$56:$J$95,$K$7,PROJETS!$AD$56:$AD$95,"Suspendu",PROJETS!$X$56:$X$95,">="&DATE($C$7,1,1),PROJETS!$X$56:$X$95,"<"&DATE($C$7+1,1,1)))) -> 0 | AO4: Reportée | AP4: =IF($C$7="Toutes les années",IF($K$7="Tous",COUNTIFS(ACTIVITES!$A$56:$A$105,"ACT*",ACTIVITES!$Z$56:$Z$105,"Reportee"),COUNTIFS(ACTIVITES!$A$56:$A$105,"ACT*",ACTIVITES!$K$56:$K$105,$K$7,ACTIVITES!$Z$56:$Z$105,"Reportee")),IF($K$7="Tous",COUNTIFS(ACTIVITES!$A$56:$A$105,"ACT*",ACTIVITES!$S$56:$S$105,$C$7,ACTIVITES!$Z$56:$Z$105,"Reportee"),COUNTIFS(ACTIVITES!$A$56:$A$105,"ACT*",ACTIVITES!$K$56:$K$105,$K$7,ACTIVITES!$S$56:$S$105,$C$7,ACTIVITES!$Z$56:$Z$105,"Reportee"))) -> 0 | AR4: 2026 | AS4: =COUNTIFS(PROJETS!$A$56:$A$95,"PROJ*",PROJETS!$X$56:$X$95,">="&DATE(AR4,1,1),PROJETS!$X$56:$X$95,"<"&DATE(AR4+1,1,1)) -> 0 | AT4: =COUNTIFS(BENEFICIAIRES!$A$56:$A$115,"BEN*",BENEFICIAIRES!$BB$56:$BB$115,">="&DATE(AR4,1,1),BENEFICIAIRES!$BB$56:$BB$115,"<"&DATE(AR4+1,1,1)) -> 0 | AU4: =SUMIFS(RECETTES!$AB$39:$AB$88,RECETTES!$V$39:$V$88,AR4) -> 0 | AV4: =SUMIFS(DEPENSES!$AG$119:$AG$168,DEPENSES!$BM$119:$BM$168,AR4) -> 0 | AW4: =COUNTIFS(ACTIVITES!$A$56:$A$105,"ACT*",ACTIVITES!$S$56:$S$105,AR4,ACTIVITES!$Z$56:$Z$105,"Realisee") -> 0 | AX4: =AR3 -> 2025 | AY4: =AS3 -> 0 | AZ4: Mars | BA4: =IF($C$7="Toutes les années",SUMIFS(RECETTES!$AB$39:$AB$88,RECETTES!$V$39:$V$88,2026,RECETTES!$W$39:$W$88,3),SUMIFS(RECETTES!$AB$39:$AB$88,RECETTES!$V$39:$V$88,$C$7,RECETTES!$W$39:$W$88,3)) -> 0 | BB4: =IF($C$7="Toutes les années",SUMIFS(DEPENSES!$AG$119:$AG$168,DEPENSES!$BM$119:$BM$168,2026,DEPENSES!$BN$119:$BN$168,3),SUMIFS(DEPENSES!$AG$119:$AG$168,DEPENSES!$BM$119:$BM$168,$C$7,DEPENSES!$BN$119:$BN$168,3)) -> 0 | BC4: =BA4-BB4 -> 0 | BE4: =AE3 -> Mars | BF4: =AF3 -> 0 | BG4: =AG3 -> 0 | BI4: =AI3 -> Terminé | BJ4: =AJ3 -> 0 | BO4: =AO3 -> Réalisée | BP4: =AP3 -> 0
B5: FILTRES DE PILOTAGE | AA5: 2027 | AB5: Avril | AC5: Culture | AE5: Mai | AF5: =IF($C$7="Toutes les années",IF($K$7="Tous",SUMIFS(RECETTES!$AB$39:$AB$88,RECETTES!$X$39:$X$88,AE5),SUMIFS(RECETTES!$AB$39:$AB$88,RECETTES!$X$39:$X$88,AE5,RECETTES!$J$39:$J$88,$K$7)),IF($K$7="Tous",SUMIFS(RECETTES!$AB$39:$AB$88,RECETTES!$V$39:$V$88,$C$7,RECETTES!$X$39:$X$88,AE5),SUMIFS(RECETTES!$AB$39:$AB$88,RECETTES!$V$39:$V$88,$C$7,RECETTES!$X$39:$X$88,AE5,RECETTES!$J$39:$J$88,$K$7))) -> 0 | AG5: =IF($C$7="Toutes les années",IF($K$7="Tous",SUMIFS(DEPENSES!$AG$119:$AG$168,DEPENSES!$BO$119:$BO$168,AE5),SUMIFS(DEPENSES!$AG$119:$AG$168,DEPENSES!$BO$119:$BO$168,AE5,DEPENSES!$G$119:$G$168,$K$7)),IF($K$7="Tous",SUMIFS(DEPENSES!$AG$119:$AG$168,DEPENSES!$BM$119:$BM$168,$C$7,DEPENSES!$BO$119:$BO$168,AE5),SUMIFS(DEPENSES!$AG$119:$AG$168,DEPENSES!$BM$119:$BM$168,$C$7,DEPENSES!$BO$119:$BO$168,AE5,DEPENSES!$G$119:$G$168,$K$7))) -> 0 | AI5: Annulé | AJ5: =IF($C$7="Toutes les années",IF($K$7="Tous",COUNTIFS(PROJETS!$A$56:$A$95,"PROJ*",PROJETS!$AD$56:$AD$95,"Annule"),COUNTIFS(PROJETS!$A$56:$A$95,"PROJ*",PROJETS!$J$56:$J$95,$K$7,PROJETS!$AD$56:$AD$95,"Annule")),IF($K$7="Tous",COUNTIFS(PROJETS!$A$56:$A$95,"PROJ*",PROJETS!$AD$56:$AD$95,"Annule",PROJETS!$X$56:$X$95,">="&DATE($C$7,1,1),PROJETS!$X$56:$X$95,"<"&DATE($C$7+1,1,1)),COUNTIFS(PROJETS!$A$56:$A$95,"PROJ*",PROJETS!$J$56:$J$95,$K$7,PROJETS!$AD$56:$AD$95,"Annule",PROJETS!$X$56:$X$95,">="&DATE($C$7,1,1),PROJETS!$X$56:$X$95,"<"&DATE($C$7+1,1,1)))) -> 0 | AO5: Annulée | AP5: =IF($C$7="Toutes les années",IF($K$7="Tous",COUNTIFS(ACTIVITES!$A$56:$A$105,"ACT*",ACTIVITES!$Z$56:$Z$105,"Annulee"),COUNTIFS(ACTIVITES!$A$56:$A$105,"ACT*",ACTIVITES!$K$56:$K$105,$K$7,ACTIVITES!$Z$56:$Z$105,"Annulee")),IF($K$7="Tous",COUNTIFS(ACTIVITES!$A$56:$A$105,"ACT*",ACTIVITES!$S$56:$S$105,$C$7,ACTIVITES!$Z$56:$Z$105,"Annulee"),COUNTIFS(ACTIVITES!$A$56:$A$105,"ACT*",ACTIVITES!$K$56:$K$105,$K$7,ACTIVITES!$S$56:$S$105,$C$7,ACTIVITES!$Z$56:$Z$105,"Annulee"))) -> 0 | AR5: 2027 | AS5: =COUNTIFS(PROJETS!$A$56:$A$95,"PROJ*",PROJETS!$X$56:$X$95,">="&DATE(AR5,1,1),PROJETS!$X$56:$X$95,"<"&DATE(AR5+1,1,1)) -> 0 | AT5: =COUNTIFS(BENEFICIAIRES!$A$56:$A$115,"BEN*",BENEFICIAIRES!$BB$56:$BB$115,">="&DATE(AR5,1,1),BENEFICIAIRES!$BB$56:$BB$115,"<"&DATE(AR5+1,1,1)) -> 0 | AU5: =SUMIFS(RECETTES!$AB$39:$AB$88,RECETTES!$V$39:$V$88,AR5) -> 0 | AV5: =SUMIFS(DEPENSES!$AG$119:$AG$168,DEPENSES!$BM$119:$BM$168,AR5) -> 0 | AW5: =COUNTIFS(ACTIVITES!$A$56:$A$105,"ACT*",ACTIVITES!$S$56:$S$105,AR5,ACTIVITES!$Z$56:$Z$105,"Realisee") -> 0 | AX5: =AR4 -> 2026 | AY5: =AS4 -> 0 | AZ5: Avril | BA5: =IF($C$7="Toutes les années",SUMIFS(RECETTES!$AB$39:$AB$88,RECETTES!$V$39:$V$88,2026,RECETTES!$W$39:$W$88,4),SUMIFS(RECETTES!$AB$39:$AB$88,RECETTES!$V$39:$V$88,$C$7,RECETTES!$W$39:$W$88,4)) -> 0 | BB5: =IF($C$7="Toutes les années",SUMIFS(DEPENSES!$AG$119:$AG$168,DEPENSES!$BM$119:$BM$168,2026,DEPENSES!$BN$119:$BN$168,4),SUMIFS(DEPENSES!$AG$119:$AG$168,DEPENSES!$BM$119:$BM$168,$C$7,DEPENSES!$BN$119:$BN$168,4)) -> 0 | BC5: =BA5-BB5 -> 0 | BE5: =AE4 -> Avril | BF5: =AF4 -> 0 | BG5: =AG4 -> 0 | BI5: =AI4 -> Suspendu | BJ5: =AJ4 -> 0 | BO5: =AO4 -> Reportée | BP5: =AP4 -> 0
B6: ANNÉE | F6: MOIS | J6: DOMAINE | N6: Les indicateurs opérationnels et financiers suivent les filtres. Les référentiels institutionnels restent cumulatifs. | AA6: 2028 | AB6: Mai | AC6: Environnement | AE6: Juin | AF6: =IF($C$7="Toutes les années",IF($K$7="Tous",SUMIFS(RECETTES!$AB$39:$AB$88,RECETTES!$X$39:$X$88,AE6),SUMIFS(RECETTES!$AB$39:$AB$88,RECETTES!$X$39:$X$88,AE6,RECETTES!$J$39:$J$88,$K$7)),IF($K$7="Tous",SUMIFS(RECETTES!$AB$39:$AB$88,RECETTES!$V$39:$V$88,$C$7,RECETTES!$X$39:$X$88,AE6),SUMIFS(RECETTES!$AB$39:$AB$88,RECETTES!$V$39:$V$88,$C$7,RECETTES!$X$39:$X$88,AE6,RECETTES!$J$39:$J$88,$K$7))) -> 0 | AG6: =IF($C$7="Toutes les années",IF($K$7="Tous",SUMIFS(DEPENSES!$AG$119:$AG$168,DEPENSES!$BO$119:$BO$168,AE6),SUMIFS(DEPENSES!$AG$119:$AG$168,DEPENSES!$BO$119:$BO$168,AE6,DEPENSES!$G$119:$G$168,$K$7)),IF($K$7="Tous",SUMIFS(DEPENSES!$AG$119:$AG$168,DEPENSES!$BM$119:$BM$168,$C$7,DEPENSES!$BO$119:$BO$168,AE6),SUMIFS(DEPENSES!$AG$119:$AG$168,DEPENSES!$BM$119:$BM$168,$C$7,DEPENSES!$BO$119:$BO$168,AE6,DEPENSES!$G$119:$G$168,$K$7))) -> 0 | AR6: 2028 | AS6: =COUNTIFS(PROJETS!$A$56:$A$95,"PROJ*",PROJETS!$X$56:$X$95,">="&DATE(AR6,1,1),PROJETS!$X$56:$X$95,"<"&DATE(AR6+1,1,1)) -> 0 | AT6: =COUNTIFS(BENEFICIAIRES!$A$56:$A$115,"BEN*",BENEFICIAIRES!$BB$56:$BB$115,">="&DATE(AR6,1,1),BENEFICIAIRES!$BB$56:$BB$115,"<"&DATE(AR6+1,1,1)) -> 0 | AU6: =SUMIFS(RECETTES!$AB$39:$AB$88,RECETTES!$V$39:$V$88,AR6) -> 0 | AV6: =SUMIFS(DEPENSES!$AG$119:$AG$168,DEPENSES!$BM$119:$BM$168,AR6) -> 0 | AW6: =COUNTIFS(ACTIVITES!$A$56:$A$105,"ACT*",ACTIVITES!$S$56:$S$105,AR6,ACTIVITES!$Z$56:$Z$105,"Realisee") -> 0 | AX6: =AR5 -> 2027 | AY6: =AS5 -> 0 | AZ6: Mai | BA6: =IF($C$7="Toutes les années",SUMIFS(RECETTES!$AB$39:$AB$88,RECETTES!$V$39:$V$88,2026,RECETTES!$W$39:$W$88,5),SUMIFS(RECETTES!$AB$39:$AB$88,RECETTES!$V$39:$V$88,$C$7,RECETTES!$W$39:$W$88,5)) -> 0 | BB6: =IF($C$7="Toutes les années",SUMIFS(DEPENSES!$AG$119:$AG$168,DEPENSES!$BM$119:$BM$168,2026,DEPENSES!$BN$119:$BN$168,5),SUMIFS(DEPENSES!$AG$119:$AG$168,DEPENSES!$BM$119:$BM$168,$C$7,DEPENSES!$BN$119:$BN$168,5)) -> 0 | BC6: =BA6-BB6 -> 0 | BE6: =AE5 -> Mai | BF6: =AF5 -> 0 | BG6: =AG5 -> 0 | BI6: =AI5 -> Annulé | BJ6: =AJ5 -> 0 | BO6: =AO5 -> Annulée | BP6: =AP5 -> 0
C7: Toutes les années | G7: Tous les mois | K7: Tous | AA7: 2029 | AB7: Juin | AC7: Sante | AE7: Juillet | AF7: =IF($C$7="Toutes les années",IF($K$7="Tous",SUMIFS(RECETTES!$AB$39:$AB$88,RECETTES!$X$39:$X$88,AE7),SUMIFS(RECETTES!$AB$39:$AB$88,RECETTES!$X$39:$X$88,AE7,RECETTES!$J$39:$J$88,$K$7)),IF($K$7="Tous",SUMIFS(RECETTES!$AB$39:$AB$88,RECETTES!$V$39:$V$88,$C$7,RECETTES!$X$39:$X$88,AE7),SUMIFS(RECETTES!$AB$39:$AB$88,RECETTES!$V$39:$V$88,$C$7,RECETTES!$X$39:$X$88,AE7,RECETTES!$J$39:$J$88,$K$7))) -> 0 | AG7: =IF($C$7="Toutes les années",IF($K$7="Tous",SUMIFS(DEPENSES!$AG$119:$AG$168,DEPENSES!$BO$119:$BO$168,AE7),SUMIFS(DEPENSES!$AG$119:$AG$168,DEPENSES!$BO$119:$BO$168,AE7,DEPENSES!$G$119:$G$168,$K$7)),IF($K$7="Tous",SUMIFS(DEPENSES!$AG$119:$AG$168,DEPENSES!$BM$119:$BM$168,$C$7,DEPENSES!$BO$119:$BO$168,AE7),SUMIFS(DEPENSES!$AG$119:$AG$168,DEPENSES!$BM$119:$BM$168,$C$7,DEPENSES!$BO$119:$BO$168,AE7,DEPENSES!$G$119:$G$168,$K$7))) -> 0 | AR7: 2029 | AS7: =COUNTIFS(PROJETS!$A$56:$A$95,"PROJ*",PROJETS!$X$56:$X$95,">="&DATE(AR7,1,1),PROJETS!$X$56:$X$95,"<"&DATE(AR7+1,1,1)) -> 0 | AT7: =COUNTIFS(BENEFICIAIRES!$A$56:$A$115,"BEN*",BENEFICIAIRES!$BB$56:$BB$115,">="&DATE(AR7,1,1),BENEFICIAIRES!$BB$56:$BB$115,"<"&DATE(AR7+1,1,1)) -> 0 | AU7: =SUMIFS(RECETTES!$AB$39:$AB$88,RECETTES!$V$39:$V$88,AR7) -> 0 | AV7: =SUMIFS(DEPENSES!$AG$119:$AG$168,DEPENSES!$BM$119:$BM$168,AR7) -> 0 | AW7: =COUNTIFS(ACTIVITES!$A$56:$A$105,"ACT*",ACTIVITES!$S$56:$S$105,AR7,ACTIVITES!$Z$56:$Z$105,"Realisee") -> 0 | AX7: =AR6 -> 2028 | AY7: =AS6 -> 0 | AZ7: Juin | BA7: =IF($C$7="Toutes les années",SUMIFS(RECETTES!$AB$39:$AB$88,RECETTES!$V$39:$V$88,2026,RECETTES!$W$39:$W$88,6),SUMIFS(RECETTES!$AB$39:$AB$88,RECETTES!$V$39:$V$88,$C$7,RECETTES!$W$39:$W$88,6)) -> 0 | BB7: =IF($C$7="Toutes les années",SUMIFS(DEPENSES!$AG$119:$AG$168,DEPENSES!$BM$119:$BM$168,2026,DEPENSES!$BN$119:$BN$168,6),SUMIFS(DEPENSES!$AG$119:$AG$168,DEPENSES!$BM$119:$BM$168,$C$7,DEPENSES!$BN$119:$BN$168,6)) -> 0 | BC7: =BA7-BB7 -> 0 | BE7: =AE6 -> Juin | BF7: =AF6 -> 0 | BG7: =AG6 -> 0
AA8: 2030 | AB8: Juillet | AC8: Genre | AE8: Août | AF8: =IF($C$7="Toutes les années",IF($K$7="Tous",SUMIFS(RECETTES!$AB$39:$AB$88,RECETTES!$X$39:$X$88,AE8),SUMIFS(RECETTES!$AB$39:$AB$88,RECETTES!$X$39:$X$88,AE8,RECETTES!$J$39:$J$88,$K$7)),IF($K$7="Tous",SUMIFS(RECETTES!$AB$39:$AB$88,RECETTES!$V$39:$V$88,$C$7,RECETTES!$X$39:$X$88,AE8),SUMIFS(RECETTES!$AB$39:$AB$88,RECETTES!$V$39:$V$88,$C$7,RECETTES!$X$39:$X$88,AE8,RECETTES!$J$39:$J$88,$K$7))) -> 0 | AG8: =IF($C$7="Toutes les années",IF($K$7="Tous",SUMIFS(DEPENSES!$AG$119:$AG$168,DEPENSES!$BO$119:$BO$168,AE8),SUMIFS(DEPENSES!$AG$119:$AG$168,DEPENSES!$BO$119:$BO$168,AE8,DEPENSES!$G$119:$G$168,$K$7)),IF($K$7="Tous",SUMIFS(DEPENSES!$AG$119:$AG$168,DEPENSES!$BM$119:$BM$168,$C$7,DEPENSES!$BO$119:$BO$168,AE8),SUMIFS(DEPENSES!$AG$119:$AG$168,DEPENSES!$BM$119:$BM$168,$C$7,DEPENSES!$BO$119:$BO$168,AE8,DEPENSES!$G$119:$G$168,$K$7))) -> 0 | AR8: 2030 | AS8: =COUNTIFS(PROJETS!$A$56:$A$95,"PROJ*",PROJETS!$X$56:$X$95,">="&DATE(AR8,1,1),PROJETS!$X$56:$X$95,"<"&DATE(AR8+1,1,1)) -> 0 | AT8: =COUNTIFS(BENEFICIAIRES!$A$56:$A$115,"BEN*",BENEFICIAIRES!$BB$56:$BB$115,">="&DATE(AR8,1,1),BENEFICIAIRES!$BB$56:$BB$115,"<"&DATE(AR8+1,1,1)) -> 0 | AU8: =SUMIFS(RECETTES!$AB$39:$AB$88,RECETTES!$V$39:$V$88,AR8) -> 0 | AV8: =SUMIFS(DEPENSES!$AG$119:$AG$168,DEPENSES!$BM$119:$BM$168,AR8) -> 0 | AW8: =COUNTIFS(ACTIVITES!$A$56:$A$105,"ACT*",ACTIVITES!$S$56:$S$105,AR8,ACTIVITES!$Z$56:$Z$105,"Realisee") -> 0 | AX8: =AR7 -> 2029 | AY8: =AS7 -> 0 | AZ8: Juillet | BA8: =IF($C$7="Toutes les années",SUMIFS(RECETTES!$AB$39:$AB$88,RECETTES!$V$39:$V$88,2026,RECETTES!$W$39:$W$88,7),SUMIFS(RECETTES!$AB$39:$AB$88,RECETTES!$V$39:$V$88,$C$7,RECETTES!$W$39:$W$88,7)) -> 0 | BB8: =IF($C$7="Toutes les années",SUMIFS(DEPENSES!$AG$119:$AG$168,DEPENSES!$BM$119:$BM$168,2026,DEPENSES!$BN$119:$BN$168,7),SUMIFS(DEPENSES!$AG$119:$AG$168,DEPENSES!$BM$119:$BM$168,$C$7,DEPENSES!$BN$119:$BN$168,7)) -> 0 | BC8: =BA8-BB8 -> 0 | BE8: =AE7 -> Juillet | BF8: =AF7 -> 0 | BG8: =AG7 -> 0
AA9: 2031 | AB9: Août | AC9: Tourisme | AE9: Septembre | AF9: =IF($C$7="Toutes les années",IF($K$7="Tous",SUMIFS(RECETTES!$AB$39:$AB$88,RECETTES!$X$39:$X$88,AE9),SUMIFS(RECETTES!$AB$39:$AB$88,RECETTES!$X$39:$X$88,AE9,RECETTES!$J$39:$J$88,$K$7)),IF($K$7="Tous",SUMIFS(RECETTES!$AB$39:$AB$88,RECETTES!$V$39:$V$88,$C$7,RECETTES!$X$39:$X$88,AE9),SUMIFS(RECETTES!$AB$39:$AB$88,RECETTES!$V$39:$V$88,$C$7,RECETTES!$X$39:$X$88,AE9,RECETTES!$J$39:$J$88,$K$7))) -> 0 | AG9: =IF($C$7="Toutes les années",IF($K$7="Tous",SUMIFS(DEPENSES!$AG$119:$AG$168,DEPENSES!$BO$119:$BO$168,AE9),SUMIFS(DEPENSES!$AG$119:$AG$168,DEPENSES!$BO$119:$BO$168,AE9,DEPENSES!$G$119:$G$168,$K$7)),IF($K$7="Tous",SUMIFS(DEPENSES!$AG$119:$AG$168,DEPENSES!$BM$119:$BM$168,$C$7,DEPENSES!$BO$119:$BO$168,AE9),SUMIFS(DEPENSES!$AG$119:$AG$168,DEPENSES!$BM$119:$BM$168,$C$7,DEPENSES!$BO$119:$BO$168,AE9,DEPENSES!$G$119:$G$168,$K$7))) -> 0 | AR9: 2031 | AS9: =COUNTIFS(PROJETS!$A$56:$A$95,"PROJ*",PROJETS!$X$56:$X$95,">="&DATE(AR9,1,1),PROJETS!$X$56:$X$95,"<"&DATE(AR9+1,1,1)) -> 0 | AT9: =COUNTIFS(BENEFICIAIRES!$A$56:$A$115,"BEN*",BENEFICIAIRES!$BB$56:$BB$115,">="&DATE(AR9,1,1),BENEFICIAIRES!$BB$56:$BB$115,"<"&DATE(AR9+1,1,1)) -> 0 | AU9: =SUMIFS(RECETTES!$AB$39:$AB$88,RECETTES!$V$39:$V$88,AR9) -> 0 | AV9: =SUMIFS(DEPENSES!$AG$119:$AG$168,DEPENSES!$BM$119:$BM$168,AR9) -> 0 | AW9: =COUNTIFS(ACTIVITES!$A$56:$A$105,"ACT*",ACTIVITES!$S$56:$S$105,AR9,ACTIVITES!$Z$56:$Z$105,"Realisee") -> 0 | AX9: =AR8 -> 2030 | AY9: =AS8 -> 0 | AZ9: Août | BA9: =IF($C$7="Toutes les années",SUMIFS(RECETTES!$AB$39:$AB$88,RECETTES!$V$39:$V$88,2026,RECETTES!$W$39:$W$88,8),SUMIFS(RECETTES!$AB$39:$AB$88,RECETTES!$V$39:$V$88,$C$7,RECETTES!$W$39:$W$88,8)) -> 0 | BB9: =IF($C$7="Toutes les années",SUMIFS(DEPENSES!$AG$119:$AG$168,DEPENSES!$BM$119:$BM$168,2026,DEPENSES!$BN$119:$BN$168,8),SUMIFS(DEPENSES!$AG$119:$AG$168,DEPENSES!$BM$119:$BM$168,$C$7,DEPENSES!$BN$119:$BN$168,8)) -> 0 | BC9: =BA9-BB9 -> 0 | BE9: =AE8 -> Août | BF9: =AF8 -> 0 | BG9: =AG8 -> 0
B10: PROJETS | F10: BÉNÉFICIAIRES | J10: ACTIVITÉS RÉALISÉES | N10: BUDGET APPROUVÉ | R10: FINANCEMENTS REÇUS | V10: DÉPENSES | AA10: 2032 | AB10: Septembre | AC10: Sport | AE10: Octobre | AF10: =IF($C$7="Toutes les années",IF($K$7="Tous",SUMIFS(RECETTES!$AB$39:$AB$88,RECETTES!$X$39:$X$88,AE10),SUMIFS(RECETTES!$AB$39:$AB$88,RECETTES!$X$39:$X$88,AE10,RECETTES!$J$39:$J$88,$K$7)),IF($K$7="Tous",SUMIFS(RECETTES!$AB$39:$AB$88,RECETTES!$V$39:$V$88,$C$7,RECETTES!$X$39:$X$88,AE10),SUMIFS(RECETTES!$AB$39:$AB$88,RECETTES!$V$39:$V$88,$C$7,RECETTES!$X$39:$X$88,AE10,RECETTES!$J$39:$J$88,$K$7))) -> 0 | AG10: =IF($C$7="Toutes les années",IF($K$7="Tous",SUMIFS(DEPENSES!$AG$119:$AG$168,DEPENSES!$BO$119:$BO$168,AE10),SUMIFS(DEPENSES!$AG$119:$AG$168,DEPENSES!$BO$119:$BO$168,AE10,DEPENSES!$G$119:$G$168,$K$7)),IF($K$7="Tous",SUMIFS(DEPENSES!$AG$119:$AG$168,DEPENSES!$BM$119:$BM$168,$C$7,DEPENSES!$BO$119:$BO$168,AE10),SUMIFS(DEPENSES!$AG$119:$AG$168,DEPENSES!$BM$119:$BM$168,$C$7,DEPENSES!$BO$119:$BO$168,AE10,DEPENSES!$G$119:$G$168,$K$7))) -> 0 | AR10: 2032 | AS10: =COUNTIFS(PROJETS!$A$56:$A$95,"PROJ*",PROJETS!$X$56:$X$95,">="&DATE(AR10,1,1),PROJETS!$X$56:$X$95,"<"&DATE(AR10+1,1,1)) -> 0 | AT10: =COUNTIFS(BENEFICIAIRES!$A$56:$A$115,"BEN*",BENEFICIAIRES!$BB$56:$BB$115,">="&DATE(AR10,1,1),BENEFICIAIRES!$BB$56:$BB$115,"<"&DATE(AR10+1,1,1)) -> 0 | AU10: =SUMIFS(RECETTES!$AB$39:$AB$88,RECETTES!$V$39:$V$88,AR10) -> 0 | AV10: =SUMIFS(DEPENSES!$AG$119:$AG$168,DEPENSES!$BM$119:$BM$168,AR10) -> 0 | AW10: =COUNTIFS(ACTIVITES!$A$56:$A$105,"ACT*",ACTIVITES!$S$56:$S$105,AR10,ACTIVITES!$Z$56:$Z$105,"Realisee") -> 0 | AX10: =AR9 -> 2031 | AY10: =AS9 -> 0 | AZ10: Septembre | BA10: =IF($C$7="Toutes les années",SUMIFS(RECETTES!$AB$39:$AB$88,RECETTES!$V$39:$V$88,2026,RECETTES!$W$39:$W$88,9),SUMIFS(RECETTES!$AB$39:$AB$88,RECETTES!$V$39:$V$88,$C$7,RECETTES!$W$39:$W$88,9)) -> 0 | BB10: =IF($C$7="Toutes les années",SUMIFS(DEPENSES!$AG$119:$AG$168,DEPENSES!$BM$119:$BM$168,2026,DEPENSES!$BN$119:$BN$168,9),SUMIFS(DEPENSES!$AG$119:$AG$168,DEPENSES!$BM$119:$BM$168,$C$7,DEPENSES!$BN$119:$BN$168,9)) -> 0 | BC10: =BA10-BB10 -> 0 | BE10: =AE9 -> Septembre | BF10: =AF9 -> 0 | BG10: =AG9 -> 0
B11: =IF($C$7="Toutes les années",IF($K$7="Tous",COUNTIF(PROJETS!$A$56:$A$95,"PROJ*"),COUNTIFS(PROJETS!$A$56:$A$95,"PROJ*",PROJETS!$J$56:$J$95,$K$7)),IF($K$7="Tous",COUNTIFS(PROJETS!$A$56:$A$95,"PROJ*",PROJETS!$X$56:$X$95,">="&DATE($C$7,1,1),PROJETS!$X$56:$X$95,"<"&DATE($C$7+1,1,1)),COUNTIFS(PROJETS!$A$56:$A$95,"PROJ*",PROJETS!$J$56:$J$95,$K$7,PROJETS!$X$56:$X$95,">="&DATE($C$7,1,1),PROJETS!$X$56:$X$95,"<"&DATE($C$7+1,1,1)))) -> 1 | F11: =IF($C$7="Toutes les années",IF($K$7="Tous",COUNTIF(BENEFICIAIRES!$A$56:$A$115,"BEN*"),COUNTIFS(BENEFICIAIRES!$A$56:$A$115,"BEN*",BENEFICIAIRES!$BA$56:$BA$115,$K$7)),IF($K$7="Tous",COUNTIFS(BENEFICIAIRES!$A$56:$A$115,"BEN*",BENEFICIAIRES!$BB$56:$BB$115,">="&DATE($C$7,1,1),BENEFICIAIRES!$BB$56:$BB$115,"<"&DATE($C$7+1,1,1)),COUNTIFS(BENEFICIAIRES!$A$56:$A$115,"BEN*",BENEFICIAIRES!$BA$56:$BA$115,$K$7,BENEFICIAIRES!$BB$56:$BB$115,">="&DATE($C$7,1,1),BENEFICIAIRES!$BB$56:$BB$115,"<"&DATE($C$7+1,1,1)))) -> 1 | J11: =IF($C$7="Toutes les années",IF($K$7="Tous",COUNTIFS(ACTIVITES!$A$56:$A$105,"ACT*",ACTIVITES!$Z$56:$Z$105,"Realisee"),COUNTIFS(ACTIVITES!$A$56:$A$105,"ACT*",ACTIVITES!$K$56:$K$105,$K$7,ACTIVITES!$Z$56:$Z$105,"Realisee")),IF($K$7="Tous",IF($G$7="Tous les mois",COUNTIFS(ACTIVITES!$A$56:$A$105,"ACT*",ACTIVITES!$S$56:$S$105,$C$7,ACTIVITES!$Z$56:$Z$105,"Realisee"),COUNTIFS(ACTIVITES!$A$56:$A$105,"ACT*",ACTIVITES!$S$56:$S$105,$C$7,ACTIVITES!$Q$56:$Q$105,$G$7,ACTIVITES!$Z$56:$Z$105,"Realisee")),IF($G$7="Tous les mois",COUNTIFS(ACTIVITES!$A$56:$A$105,"ACT*",ACTIVITES!$K$56:$K$105,$K$7,ACTIVITES!$S$56:$S$105,$C$7,ACTIVITES!$Z$56:$Z$105,"Realisee"),COUNTIFS(ACTIVITES!$A$56:$A$105,"ACT*",ACTIVITES!$K$56:$K$105,$K$7,ACTIVITES!$S$56:$S$105,$C$7,ACTIVITES!$Q$56:$Q$105,$G$7,ACTIVITES!$Z$56:$Z$105,"Realisee")))) -> 0 | N11: =IF($C$7="Toutes les années",IF($K$7="Tous",SUM(BUDGET!$AB$28:$AB$67),SUMIFS(BUDGET!$AB$28:$AB$67,BUDGET!$J$28:$J$67,$K$7)),IF($K$7="Tous",SUMIFS(BUDGET!$AB$28:$AB$67,BUDGET!$B$28:$B$67,$C$7),SUMIFS(BUDGET!$AB$28:$AB$67,BUDGET!$B$28:$B$67,$C$7,BUDGET!$J$28:$J$67,$K$7))) -> 0 | R11: =IF($C$7="Toutes les années",IF($K$7="Tous",SUM(RECETTES!$AB$39:$AB$88),SUMIFS(RECETTES!$AB$39:$AB$88,RECETTES!$J$39:$J$88,$K$7)),IF($K$7="Tous",SUMIFS(RECETTES!$AB$39:$AB$88,RECETTES!$V$39:$V$88,$C$7),SUMIFS(RECETTES!$AB$39:$AB$88,RECETTES!$V$39:$V$88,$C$7,RECETTES!$J$39:$J$88,$K$7))) -> 0 | V11: =IF($C$7="Toutes les années",IF($K$7="Tous",SUM(DEPENSES!$AG$119:$AG$168),SUMIFS(DEPENSES!$AG$119:$AG$168,DEPENSES!$G$119:$G$168,$K$7)),IF($K$7="Tous",SUMIFS(DEPENSES!$AG$119:$AG$168,DEPENSES!$BM$119:$BM$168,$C$7),SUMIFS(DEPENSES!$AG$119:$AG$168,DEPENSES!$BM$119:$BM$168,$C$7,DEPENSES!$G$119:$G$168,$K$7))) -> 29999 | AA11: 2033 | AB11: Octobre | AC11: Agriculture et developpement rural | AE11: Novembre | AF11: =IF($C$7="Toutes les années",IF($K$7="Tous",SUMIFS(RECETTES!$AB$39:$AB$88,RECETTES!$X$39:$X$88,AE11),SUMIFS(RECETTES!$AB$39:$AB$88,RECETTES!$X$39:$X$88,AE11,RECETTES!$J$39:$J$88,$K$7)),IF($K$7="Tous",SUMIFS(RECETTES!$AB$39:$AB$88,RECETTES!$V$39:$V$88,$C$7,RECETTES!$X$39:$X$88,AE11),SUMIFS(RECETTES!$AB$39:$AB$88,RECETTES!$V$39:$V$88,$C$7,RECETTES!$X$39:$X$88,AE11,RECETTES!$J$39:$J$88,$K$7))) -> 0 | AG11: =IF($C$7="Toutes les années",IF($K$7="Tous",SUMIFS(DEPENSES!$AG$119:$AG$168,DEPENSES!$BO$119:$BO$168,AE11),SUMIFS(DEPENSES!$AG$119:$AG$168,DEPENSES!$BO$119:$BO$168,AE11,DEPENSES!$G$119:$G$168,$K$7)),IF($K$7="Tous",SUMIFS(DEPENSES!$AG$119:$AG$168,DEPENSES!$BM$119:$BM$168,$C$7,DEPENSES!$BO$119:$BO$168,AE11),SUMIFS(DEPENSES!$AG$119:$AG$168,DEPENSES!$BM$119:$BM$168,$C$7,DEPENSES!$BO$119:$BO$168,AE11,DEPENSES!$G$119:$G$168,$K$7))) -> 0 | AR11: 2033 | AS11: =COUNTIFS(PROJETS!$A$56:$A$95,"PROJ*",PROJETS!$X$56:$X$95,">="&DATE(AR11,1,1),PROJETS!$X$56:$X$95,"<"&DATE(AR11+1,1,1)) -> 0 | AT11: =COUNTIFS(BENEFICIAIRES!$A$56:$A$115,"BEN*",BENEFICIAIRES!$BB$56:$BB$115,">="&DATE(AR11,1,1),BENEFICIAIRES!$BB$56:$BB$115,"<"&DATE(AR11+1,1,1)) -> 0 | AU11: =SUMIFS(RECETTES!$AB$39:$AB$88,RECETTES!$V$39:$V$88,AR11) -> 0 | AV11: =SUMIFS(DEPENSES!$AG$119:$AG$168,DEPENSES!$BM$119:$BM$168,AR11) -> 0 | AW11: =COUNTIFS(ACTIVITES!$A$56:$A$105,"ACT*",ACTIVITES!$S$56:$S$105,AR11,ACTIVITES!$Z$56:$Z$105,"Realisee") -> 0 | AX11: =AR10 -> 2032 | AY11: =AS10 -> 0 | AZ11: Octobre | BA11: =IF($C$7="Toutes les années",SUMIFS(RECETTES!$AB$39:$AB$88,RECETTES!$V$39:$V$88,2026,RECETTES!$W$39:$W$88,10),SUMIFS(RECETTES!$AB$39:$AB$88,RECETTES!$V$39:$V$88,$C$7,RECETTES!$W$39:$W$88,10)) -> 0 | BB11: =IF($C$7="Toutes les années",SUMIFS(DEPENSES!$AG$119:$AG$168,DEPENSES!$BM$119:$BM$168,2026,DEPENSES!$BN$119:$BN$168,10),SUMIFS(DEPENSES!$AG$119:$AG$168,DEPENSES!$BM$119:$BM$168,$C$7,DEPENSES!$BN$119:$BN$168,10)) -> 0 | BC11: =BA11-BB11 -> 0 | BE11: =AE10 -> Octobre | BF11: =AF10 -> 0 | BG11: =AG10 -> 0
AB12: Novembre | AC12: Elevage | AE12: Décembre | AF12: =IF($C$7="Toutes les années",IF($K$7="Tous",SUMIFS(RECETTES!$AB$39:$AB$88,RECETTES!$X$39:$X$88,AE12),SUMIFS(RECETTES!$AB$39:$AB$88,RECETTES!$X$39:$X$88,AE12,RECETTES!$J$39:$J$88,$K$7)),IF($K$7="Tous",SUMIFS(RECETTES!$AB$39:$AB$88,RECETTES!$V$39:$V$88,$C$7,RECETTES!$X$39:$X$88,AE12),SUMIFS(RECETTES!$AB$39:$AB$88,RECETTES!$V$39:$V$88,$C$7,RECETTES!$X$39:$X$88,AE12,RECETTES!$J$39:$J$88,$K$7))) -> 0 | AG12: =IF($C$7="Toutes les années",IF($K$7="Tous",SUMIFS(DEPENSES!$AG$119:$AG$168,DEPENSES!$BO$119:$BO$168,AE12),SUMIFS(DEPENSES!$AG$119:$AG$168,DEPENSES!$BO$119:$BO$168,AE12,DEPENSES!$G$119:$G$168,$K$7)),IF($K$7="Tous",SUMIFS(DEPENSES!$AG$119:$AG$168,DEPENSES!$BM$119:$BM$168,$C$7,DEPENSES!$BO$119:$BO$168,AE12),SUMIFS(DEPENSES!$AG$119:$AG$168,DEPENSES!$BM$119:$BM$168,$C$7,DEPENSES!$BO$119:$BO$168,AE12,DEPENSES!$G$119:$G$168,$K$7))) -> 0 | AZ12: Novembre | BA12: =IF($C$7="Toutes les années",SUMIFS(RECETTES!$AB$39:$AB$88,RECETTES!$V$39:$V$88,2026,RECETTES!$W$39:$W$88,11),SUMIFS(RECETTES!$AB$39:$AB$88,RECETTES!$V$39:$V$88,$C$7,RECETTES!$W$39:$W$88,11)) -> 0 | BB12: =IF($C$7="Toutes les années",SUMIFS(DEPENSES!$AG$119:$AG$168,DEPENSES!$BM$119:$BM$168,2026,DEPENSES!$BN$119:$BN$168,11),SUMIFS(DEPENSES!$AG$119:$AG$168,DEPENSES!$BM$119:$BM$168,$C$7,DEPENSES!$BN$119:$BN$168,11)) -> 0 | BC12: =BA12-BB12 -> 0 | BE12: =AE11 -> Novembre | BF12: =AF11 -> 0 | BG12: =AG11 -> 0
AB13: Décembre | AC13: Peche et aquaculture | AZ13: Décembre | BA13: =IF($C$7="Toutes les années",SUMIFS(RECETTES!$AB$39:$AB$88,RECETTES!$V$39:$V$88,2026,RECETTES!$W$39:$W$88,12),SUMIFS(RECETTES!$AB$39:$AB$88,RECETTES!$V$39:$V$88,$C$7,RECETTES!$W$39:$W$88,12)) -> 0 | BB13: =IF($C$7="Toutes les années",SUMIFS(DEPENSES!$AG$119:$AG$168,DEPENSES!$BM$119:$BM$168,2026,DEPENSES!$BN$119:$BN$168,12),SUMIFS(DEPENSES!$AG$119:$AG$168,DEPENSES!$BM$119:$BM$168,$C$7,DEPENSES!$BN$119:$BN$168,12)) -> 0 | BC13: =BA13-BB13 -> 0 | BE13: =AE12 -> Décembre | BF13: =AF12 -> 0 | BG13: =AG12 -> 0
AC14: Securite alimentaire et nutrition
B15: SOLDE BUDGÉTAIRE | F15: TAUX D'EXÉCUTION | J15: PERFORMANCE PROJETS | N15: PARTENAIRES ACTIFS | R15: DONATEURS ACTIFS | V15: RH ACTIVES | AC15: Eau, hygiene et assainissement
B16: =N11-V11 -> -29999 | F16: =IFERROR(V11/N11,0) -> 0 | J16: =IF($C$7="Toutes les années",IFERROR(AVERAGEIF(PROJETS!$A$56:$A$95,"PROJ*",PROJETS!$BD$56:$BD$95),0),IFERROR(AVERAGEIFS(PROJETS!$BD$56:$BD$95,PROJETS!$A$56:$A$95,"PROJ*",PROJETS!$X$56:$X$95,">="&DATE($C$7,1,1),PROJETS!$X$56:$X$95,"<"&DATE($C$7+1,1,1)),0)) -> 0.45 | N16: =COUNTIFS(PARTENAIRES!$A$56:$A$115,"PART*",PARTENAIRES!$AN$56:$AN$115,"Actif") -> 0 | R16: =COUNTIFS(DONATEURS!$A$56:$A$205,"DON*",DONATEURS!$AB$56:$AB$205,"Actif") -> 0 | V16: =COUNTIFS('RESSOURCES HUMAINES'!$A$27:$A$76,"RH*",'RESSOURCES HUMAINES'!$P$27:$P$76,"Actif") -> 0 | AC16: Protection sociale
AC17: Protection de l'enfance
AC18: Jeunesse
AC19: Autonomisation des femmes
B20: FINANCES — RECETTES VS DÉPENSES | N20: PORTEFEUILLE DES PROJETS — STATUT | AC20: Developpement communautaire
AC21: Inclusion sociale
AC22: Handicap et inclusion des personnes vulnerables
AC23: Emploi et insertion professionnelle
AC24: Developpement economique local
AC25: Artisanat
AC26: Numerique et transformation digitale
AC27: Technologies et innovation
AC28: Recherche et developpement
AC29: Gouvernance et citoyennete
AC30: Droits humains
AC31: Paix, cohesion sociale et prevention des conflits
AC32: Action humanitaire et gestion des urgences
... AC34: Gestion durable des ressources naturelles
AA35: ALERTES | AC35: Biodiversite et conservation | AD35: FINANCES
B36: BÉNÉFICIAIRES — RÉPARTITION PAR SEXE | N36: ACTIVITÉS — STATUT D'AVANCEMENT | AA36: Projets en retard | AB36: =B54 -> 1 | AC36: Infrastructures et equipements communautaires | AD36: Budget approuvé | AE36: =N11 -> 0
AA37: Dépassements budgétaires | AB37: =J54 -> 0 | AC37: Developpement urbain et territorial | AD37: Financements reçus | AE37: =R11 -> 0
AA38: Dépenses en anomalie | AB38: =R54 -> 0 | AC38: Communication et information | AD38: Dépenses | AE38: =V11 -> 29999
AA39: S&E en alerte | AB39: =B57 -> 0 | AC39: Mobilite et echanges culturels
AA40: Activités en retard | AB40: =J57 -> 0 | AC40: Patrimoine et tourisme culturel
AA41: Donateurs à relancer | AB41: =R57 -> 0 | AC41: Autre domaine
B52: ÉVOLUTION & COURBES KPI — 2024 À 2033
...

Sheet ONG
A1: O.N.G BK — FICHE D'IDENTIFICATION ET D'INFORMATIONS INSTITUTIONNELLES | L1: SOMMAIRE ACTUALISÉ | N1: SOMMAIRE ACTUALISÉ – ONG BK
A2: Referentiel institutionnel du classeur — Donnons la joie a la jeunesse | L2: Total ONG | M2: =COUNTA(B270:B469) -> 14 | N2: Registre des membres | O2: =COUNTA(B270:B469) -> 14
A3: Date de derniere mise a jour : | D3: Annee de reference : | F3: Statut de l'organisation : | G3: Actif | L3: Femmes | M3: =COUNTIF(D270:D469,"Femme") -> 6 | N3: Effectif total | O3: =COUNTA(B270:B469) -> 14
L4: Hommes | M4: =COUNTIF(D270:D469,"Homme") -> 8 | N4: Femmes | O4: =COUNTIF(D270:D469,"Femme") -> 6
A5: LEGENDE : texte bleu = champ a completer par l'ONG | texte vert italique = recupere automatiquement depuis PARAMETRES (ou une future feuille) | valeur grisee en indicateur = sera calculee automatiquement des la creation de la feuille source correspondante | L5: BE | M5: =COUNTIF(H270:H469,"BE") -> 7 | N5: Hommes | O5: =COUNTIF(D270:D469,"Homme") -> 8
L6: Membres CCE | M6: =COUNTIF(H270:H469,"CCE") -> 2 | N6: Bureau exécutif (BE) | O6: =COUNTIF(H270:H469,"BE") -> 7
A7: SOMMAIRE — cliquez sur une section pour y acceder | N7: CCE | O7: =COUNTIF(H270:H469,"CCE") -> 2
A8: 1. IDENTITE DE L'ONG | G8: fiche | N8: Membres | O8: =COUNTIF(H270:H469,"Membre") -> 5
A9: 2. INFORMATIONS JURIDIQUES | G9: fiche
A10: 3. SIEGE ET LOCALISATION | G10: fiche
A11: 4. CONTACTS OFFICIELS | G11: tableau | N11: Année | O11: Effectif total | P11: Femmes | Q11: Hommes | R11: BE | S11: CCE
A12: 5. VISION | G12: zone de texte | N12: 2020 | O12: =COUNTIF($I$270:$I$469,N12) -> 0 | P12: =COUNTIFS($I$270:$I$469,N12,$D$270:$D$469,"Femme") -> 0 | Q12: =COUNTIFS($I$270:$I$469,N12,$D$270:$D$469,"Homme") -> 0 | R12: =COUNTIFS($I$270:$I$469,N12,$H$270:$H$469,"BE") -> 0 | S12: =COUNTIFS($I$270:$I$469,N12,$H$270:$H$469,"CCE") -> 0
A13: 6. MISSION | G13: zone de texte | N13: 2021 | O13: =COUNTIF($I$270:$I$469,N13) -> 0 | P13: =COUNTIFS($I$270:$I$469,N13,$D$270:$D$469,"Femme") -> 0 | Q13: =COUNTIFS($I$270:$I$469,N13,$D$270:$D$469,"Homme") -> 0 | R13: =COUNTIFS($I$270:$I$469,N13,$H$270:$H$469,"BE") -> 0 | S13: =COUNTIFS($I$270:$I$469,N13,$H$270:$H$469,"CCE") -> 0
A14: 7. VALEURS | G14: tableau | N14: 2022 | O14: =COUNTIF($I$270:$I$469,N14) -> 0 | P14: =COUNTIFS($I$270:$I$469,N14,$D$270:$D$469,"Femme") -> 0 | Q14: =COUNTIFS($I$270:$I$469,N14,$D$270:$D$469,"Homme") -> 0 | R14: =COUNTIFS($I$270:$I$469,N14,$H$270:$H$469,"BE") -> 0 | S14: =COUNTIFS($I$270:$I$469,N14,$H$270:$H$469,"CCE") -> 0
A15: 8. OBJECTIFS STRATEGIQUES | G15: tableau | N15: 2023 | O15: =COUNTIF($I$270:$I$469,N15) -> 0 | P15: =COUNTIFS($I$270:$I$469,N15,$D$270:$D$469,"Femme") -> 0 | Q15: =COUNTIFS($I$270:$I$469,N15,$D$270:$D$469,"Homme") -> 0 | R15: =COUNTIFS($I$270:$I$469,N15,$H$270:$H$469,"BE") -> 0 | S15: =COUNTIFS($I$270:$I$469,N15,$H$270:$H$469,"CCE") -> 0
A16: 9. DOMAINES D'INTERVENTION | G16: tableau | N16: 2024 | O16: =COUNTIF($I$270:$I$469,N16) -> 14 | P16: =COUNTIFS($I$270:$I$469,N16,$D$270:$D$469,"Femme") -> 6 | Q16: =COUNTIFS($I$270:$I$469,N16,$D$270:$D$469,"Homme") -> 8 | R16: =COUNTIFS($I$270:$I$469,N16,$H$270:$H$469,"BE") -> 7 | S16: =COUNTIFS($I$270:$I$469,N16,$H$270:$H$469,"CCE") -> 2
A17: 10. ZONES D'INTERVENTION | G17: tableau | N17: 2025 | O17: =COUNTIF($I$270:$I$469,N17) -> 0 | P17: =COUNTIFS($I$270:$I$469,N17,$D$270:$D$469,"Femme") -> 0 | Q17: =COUNTIFS($I$270:$I$469,N17,$D$270:$D$469,"Homme") -> 0 | R17: =COUNTIFS($I$270:$I$469,N17,$H$270:$H$469,"BE") -> 0 | S17: =COUNTIFS($I$270:$I$469,N17,$H$270:$H$469,"CCE") -> 0
A18: 11. ORGANISATION INTERNE | G18: tableau | N18: 2026 | O18: =COUNTIF($I$270:$I$469,N18) -> 0 | P18: =COUNTIFS($I$270:$I$469,N18,$D$270:$D$469,"Femme") -> 0 | Q18: =COUNTIFS($I$270:$I$469,N18,$D$270:$D$469,"Homme") -> 0 | R18: =COUNTIFS($I$270:$I$469,N18,$H$270:$H$469,"BE") -> 0 | S18: =COUNTIFS($I$270:$I$469,N18,$H$270:$H$469,"CCE") -> 0
A19: 12. EFFECTIF GLOBAL | G19: indicateurs | N19: 2027 | O19: =COUNTIF($I$270:$I$469,N19) -> 0 | P19: =COUNTIFS($I$270:$I$469,N19,$D$270:$D$469,"Femme") -> 0 | Q19: =COUNTIFS($I$270:$I$469,N19,$D$270:$D$469,"Homme") -> 0 | R19: =COUNTIFS($I$270:$I$469,N19,$H$270:$H$469,"BE") -> 0 | S19: =COUNTIFS($I$270:$I$469,N19,$H$270:$H$469,"CCE") -> 0
A20: 13. PARTENARIATS INSTITUTIONNELS | G20: tableau | N20: 2028 | O20: =COUNTIF($I$270:$I$469,N20) -> 0 | P20: =COUNTIFS($I$270:$I$469,N20,$D$270:$D$469,"Femme") -> 0 | Q20: =COUNTIFS($I$270:$I$469,N20,$D$270:$D$469,"Homme") -> 0 | R20: =COUNTIFS($I$270:$I$469,N20,$H$270:$H$469,"BE") -> 0 | S20: =COUNTIFS($I$270:$I$469,N20,$H$270:$H$469,"CCE") -> 0
A21: 14. SOURCES DE FINANCEMENT | G21: tableau | N21: 2029 | O21: =COUNTIF($I$270:$I$469,N21) -> 0 | P21: =COUNTIFS($I$270:$I$469,N21,$D$270:$D$469,"Femme") -> 0 | Q21: =COUNTIFS($I$270:$I$469,N21,$D$270:$D$469,"Homme") -> 0 | R21: =COUNTIFS($I$270:$I$469,N21,$H$270:$H$469,"BE") -> 0 | S21: =COUNTIFS($I$270:$I$469,N21,$H$270:$H$469,"CCE") -> 0
A22: 15. DOCUMENTS OFFICIELS | G22: tableau | N22: 2030 | O22: =COUNTIF($I$270:$I$469,N22) -> 0 | P22: =COUNTIFS($I$270:$I$469,N22,$D$270:$D$469,"Femme") -> 0 | Q22: =COUNTIFS($I$270:$I$469,N22,$D$270:$D$469,"Homme") -> 0 | R22: =COUNTIFS($I$270:$I$469,N22,$H$270:$H$469,"BE") -> 0 | S22: =COUNTIFS($I$270:$I$469,N22,$H$270:$H$469,"CCE") -> 0
A23: 16. INFORMATIONS BANCAIRES | G23: tableau | N23: 2031 | O23: =COUNTIF($I$270:$I$469,N23) -> 0 | P23: =COUNTIFS($I$270:$I$469,N23,$D$270:$D$469,"Femme") -> 0 | Q23: =COUNTIFS($I$270:$I$469,N23,$D$270:$D$469,"Homme") -> 0 | R23: =COUNTIFS($I$270:$I$469,N23,$H$270:$H$469,"BE") -> 0 | S23: =COUNTIFS($I$270:$I$469,N23,$H$270:$H$469,"CCE") -> 0
... A27: 20. GOUVERNANCE - ORGANES | G27: tableau | N27: 2035 | O27: =COUNTIF($I$270:$I$469,N27) -> 0 | P27: =COUNTIFS($I$270:$I$469,N27,$D$270:$D$469,"Femme") -> 0 | Q27: =COUNTIFS($I$270:$I$469,N27,$D$270:$D$469,"Homme") -> 0 | R27: =COUNTIFS($I$270:$I$469,N27,$H$270:$H$469,"BE") -> 0 | S27: =COUNTIFS($I$270:$I$469,N27,$H$270:$H$469,"CCE") -> 0
A28: 21. REUNIONS ET GOUVERNANCE | G28: tableau
A29: 22. INDICATEURS INSTITUTIONNELS | G29: indicateurs
A30: 23. HISTORIQUE DES MODIFICATIONS | G30: tableau
A32: 1. IDENTITE DE L'ONG
A33: Nom officiel de l'ONG | C33: O.N.G BK
A34: Sigle | C34: BK O.N.G
A35: Nom court | C35: BK
A36: Type d'organisation
A37: Statut juridique
A38: Date de creation
A39: Date de reconnaissance officielle
A40: Numero d'enregistrement
A41: Numero d'agrement
A42: Numero d'identification fiscale (si applicable)
A43: Pays d'enregistrement | C43: Congo
A44: Annee de creation
...

Sheet BENEFICIAIRES
A1: O.N.G BK — BASE DE DONNEES DES BENEFICIAIRES | Q1: -> ONG
A2: Annee de reference : | D2: 2026 | F2: Derniere mise a jour : | I2: =TODAY() -> 46305 | K2: Nombre total de beneficiaires : | O2: =COUNTIF(tbl_Beneficiaires[ID Beneficiaire],"BEN*") -> 1 | Q2: -> PARAMETRES
A4: LEGENDE : texte bleu = champ a completer manuellement | texte vert italique = donnee calculee automatiquement | ne pas modifier les colonnes calculees.
A6: SYNTHESE GENERALE (calcul automatique)
A7: Total beneficiaires | B7: Hommes | C7: Femmes | D7: Autres / non precise | E7: Enfants (0-17 ans) | F7: Jeunes (18-24 ans) | G7: Adultes (25-64 ans) | H7: Personnes agees (65+) | I7: Personnes handicap | J7: Menages distincts | K7: Actifs | L7: Sortis du programme | M7: Année sélectionnée | N7: Total
A8: =IF($N$7="Total",COUNTIF(A56:A115,"BEN*"),COUNTIFS(A56:A115,"BEN*",BB56:BB115,">="&DATE(VALUE($N$7),1,1),BB56:BB115,"<"&DATE(VALUE($N$7)+1,1,1))) -> 1 | B8: =IF($N$7="Total",COUNTIFS(A56:A115,"BEN*",H56:H115,"Masculin"),COUNTIFS(A56:A115,"BEN*",H56:H115,"Masculin",BB56:BB115,">="&DATE(VALUE($N$7),1,1),BB56:BB115,"<"&DATE(VALUE($N$7)+1,1,1))) -> 0 | C8: =IF($N$7="Total",COUNTIFS(A56:A115,"BEN*",H56:H115,"Feminin"),COUNTIFS(A56:A115,"BEN*",H56:H115,"Feminin",BB56:BB115,">="&DATE(VALUE($N$7),1,1),BB56:BB115,"<"&DATE(VALUE($N$7)+1,1,1))) -> 1 | D8: =IF($N$7="Total",COUNTIFS(A56:A115,"BEN*",H56:H115,"Non precise"),COUNTIFS(A56:A115,"BEN*",H56:H115,"Non precise",BB56:BB115,">="&DATE(VALUE($N$7),1,1),BB56:BB115,"<"&DATE(VALUE($N$7)+1,1,1))) -> 0 | E8: =IF($N$7="Total",COUNTIFS(A56:A115,"BEN*",J56:J115,"<18"),COUNTIFS(A56:A115,"BEN*",J56:J115,"<18",BB56:BB115,">="&DATE(VALUE($N$7),1,1),BB56:BB115,"<"&DATE(VALUE($N$7)+1,1,1))) -> 0 | F8: =IF($N$7="Total",COUNTIFS(A56:A115,"BEN*",J56:J115,">=18",J56:J115,"<=24"),COUNTIFS(A56:A115,"BEN*",J56:J115,">=18",J56:J115,"<=24",BB56:BB115,">="&DATE(VALUE($N$7),1,1),BB56:BB115,"<"&DATE(VALUE($N$7)+1,1,1))) -> 1 | G8: =IF($N$7="Total",COUNTIFS(A56:A115,"BEN*",J56:J115,">=25",J56:J115,"<=64"),COUNTIFS(A56:A115,"BEN*",J56:J115,">=25",J56:J115,"<=64",BB56:BB115,">="&DATE(VALUE($N$7),1,1),BB56:BB115,"<"&DATE(VALUE($N$7)+1,1,1))) -> 0 | H8: =IF($N$7="Total",COUNTIFS(A56:A115,"BEN*",J56:J115,">=65"),COUNTIFS(A56:A115,"BEN*",J56:J115,">=65",BB56:BB115,">="&DATE(VALUE($N$7),1,1),BB56:BB115,"<"&DATE(VALUE($N$7)+1,1,1))) -> 0 | I8: =IF($N$7="Total",COUNTIFS(A56:A115,"BEN*",V56:V115,"Oui"),COUNTIFS(A56:A115,"BEN*",V56:V115,"Oui",BB56:BB115,">="&DATE(VALUE($N$7),1,1),BB56:BB115,"<"&DATE(VALUE($N$7)+1,1,1))) -> 0 | J8: =IF($N$7="Total",SUMPRODUCT((N56:N115<>"")/COUNTIF(N56:N115,N56:N115&"")),SUMPRODUCT((N56:N115<>"")*(BB56:BB115>=DATE(VALUE($N$7),1,1))*(BB56:BB115<DATE(VALUE($N$7)+1,1,1))/COUNTIFS(N56:N115,N56:N115,BB56:BB115,">="&DATE(VALUE($N$7),1,1),BB56:BB115,"<"&DATE(VALUE($N$7)+1,1,1)))) -> 0 | K8: =IF($N$7="Total",COUNTIFS(A56:A115,"BEN*",BD56:BD115,"Actif"),COUNTIFS(A56:A115,"BEN*",BD56:BD115,"Actif",BB56:BB115,">="&DATE(VALUE($N$7),1,1),BB56:BB115,"<"&DATE(VALUE($N$7)+1,1,1))) -> 1 | L8: =IF($N$7="Total",COUNTIFS(A56:A115,"BEN*",BD56:BD115,"Sorti du programme"),COUNTIFS(A56:A115,"BEN*",BD56:BD115,"Sorti du programme",BB56:BB115,">="&DATE(VALUE($N$7),1,1),BB56:BB115,"<"&DATE(VALUE($N$7)+1,1,1))) -> 0
A10: ANALYSES AUTOMATIQUES (alimentent le futur TABLEAU DE BORD)
A11: Domaine d'intervention | B11: Nb beneficiaires | D11: Departement | E11: Nb beneficiaires | G11: Projet (nom) | H11: Nb beneficiaires
A12: Education | B12: =COUNTIFS(tbl_Beneficiaires[Domaine d''intervention],A12) -> 1 | D12: Brazzaville | E12: =COUNTIFS(tbl_Beneficiaires[Departement],D12) -> 1 | H12: =IF(G12="","",COUNTIFS(tbl_Beneficiaires[Nom du projet],G12))
A13: Formation professionnelle | B13: =COUNTIFS(tbl_Beneficiaires[Domaine d''intervention],A13) -> 0 | D13: Pointe-Noire | E13: =COUNTIFS(tbl_Beneficiaires[Departement],D13) -> 0 | H13: =IF(G13="","",COUNTIFS(tbl_Beneficiaires[Nom du projet],G13))
A14: Entrepreneuriat | B14: =COUNTIFS(tbl_Beneficiaires[Domaine d''intervention],A14) -> 0 | E14: =IF(D14="","",COUNTIFS(tbl_Beneficiaires[Departement],D14)) | H14: =IF(G14="","",COUNTIFS(tbl_Beneficiaires[Nom du projet],G14))
A15: Culture | B15: =COUNTIFS(tbl_Beneficiaires[Domaine d''intervention],A15) -> 0 | E15: =IF(D15="","",COUNTIFS(tbl_Beneficiaires[Departement],D15)) | H15: =IF(G15="","",COUNTIFS(tbl_Beneficiaires[Nom du projet],G15))
A16: Environnement | B16: =COUNTIFS(tbl_Beneficiaires[Domaine d''intervention],A16) -> 0 | E16: =IF(D16="","",COUNTIFS(tbl_Beneficiaires[Departement],D16)) | H16: =IF(G16="","",COUNTIFS(tbl_Beneficiaires[Nom du projet],G16))
A17: Sante | B17: =COUNTIFS(tbl_Beneficiaires[Domaine d''intervention],A17) -> 0 | E17: =IF(D17="","",COUNTIFS(tbl_Beneficiaires[Departement],D17)) | H17: =IF(G17="","",COUNTIFS(tbl_Beneficiaires[Nom du projet],G17))
A18: Genre | B18: =COUNTIFS(tbl_Beneficiaires[Domaine d''intervention],A18) -> 0 | E18: =IF(D18="","",COUNTIFS(tbl_Beneficiaires[Departement],D18)) | H18: =IF(G18="","",COUNTIFS(tbl_Beneficiaires[Nom du projet],G18))
A19: Tourisme | B19: =COUNTIFS(tbl_Beneficiaires[Domaine d''intervention],A19) -> 0 | E19: =IF(D19="","",COUNTIFS(tbl_Beneficiaires[Departement],D19)) | H19: =IF(G19="","",COUNTIFS(tbl_Beneficiaires[Nom du projet],G19))
A20: Sport | B20: =COUNTIFS(tbl_Beneficiaires[Domaine d''intervention],A20) -> 0 | E20: =IF(D20="","",COUNTIFS(tbl_Beneficiaires[Departement],D20)) | H20: =IF(G20="","",COUNTIFS(tbl_Beneficiaires[Nom du projet],G20))
A21: Agriculture et developpement rural | B21: =COUNTIFS(tbl_Beneficiaires[Domaine d''intervention],A21) -> 0 | E21: =IF(D21="","",COUNTIFS(tbl_Beneficiaires[Departement],D21)) | H21: =IF(G21="","",COUNTIFS(tbl_Beneficiaires[Nom du projet],G21))
A22: Elevage | B22: =COUNTIFS(tbl_Beneficiaires[Domaine d''intervention],A22) -> 0
A23: Peche et aquaculture | B23: =COUNTIFS(tbl_Beneficiaires[Domaine d''intervention],A23) -> 0 | G23: -> saisir un nom de projet par ligne ci-dessus ; a connecter automatiquement des la creation de la feuille PROJETS.
A24: Securite alimentaire et nutrition | B24: =COUNTIFS(tbl_Beneficiaires[Domaine d''intervention],A24) -> 0
A25: Eau, hygiene et assainissement | B25: =COUNTIFS(tbl_Beneficiaires[Domaine d''intervention],A25) -> 0
A26: Protection sociale | B26: =COUNTIFS(tbl_Beneficiaires[Domaine d''intervention],A26) -> 0
A27: Protection de l'enfance | B27: =COUNTIFS(tbl_Beneficiaires[Domaine d''intervention],A27) -> 0
A28: Jeunesse | B28: =COUNTIFS(tbl_Beneficiaires[Domaine d''intervention],A28) -> 0
A29: Autonomisation des femmes | B29: =COUNTIFS(tbl_Beneficiaires[Domaine d''intervention],A29) -> 0
A30: Developpement communautaire | B30: =COUNTIFS(tbl_Beneficiaires[Domaine d''intervention],A30) -> 0
A31: Inclusion sociale | B31: =COUNTIFS(tbl_Beneficiaires[Domaine d''intervention],A31) -> 0
A32: Handicap et inclusion des personnes vulnerables | B32: =COUNTIFS(tbl_Beneficiaires[Domaine d''intervention],A32) -> 0
A33: Emploi et insertion professionnelle | B33: =COUNTIFS(tbl_Beneficiaires[Domaine d''intervention],A33) -> 0
A34: Developpement economique local | B34: =COUNTIFS(tbl_Beneficiaires[Domaine d''intervention],A34) -> 0
A35: Artisanat | B35: =COUNTIFS(tbl_Beneficiaires[Domaine d''intervention],A35) -> 0
... A51: Autre domaine | B51: =COUNTIFS(tbl_Beneficiaires[Domaine d''intervention],A51) -> 0
A54: TABLEAU PRINCIPAL — LISTE DES BENEFICIAIRES
A55: ID Beneficiaire | B55: Type de beneficiaire | C55: Categorie beneficiaire | D55: Nom | E55: Postnom | F55: Prenom | G55: Nom complet | H55: Sexe | I55: Date de naissance | J55: Age | K55: Tranche d'age | L55: Situation matrimoniale | M55: Nationalite | N55: ID menage | O55: Nom du menage | P55: Taille du menage | Q55: Responsable du menage | R55: Nb hommes menage | S55: Nb femmes menage | T55: Nb enfants menage | U55: Nb pers. vulnerables menage | V55: Handicap | W55: Enfant vulnerable | X55: Pers. agee vulnerable | Y55: Femme vulnerable | Z55: Menage vulnerable | AA55: Personne deplacee | AB55: Autre vulnerabilite | AC55: Niveau instruction | AD55: Situation professionnelle | AE55: Profession | AF55: Secteur d'activite | AG55: Statut professionnel | AH55: Niveau de revenu | AI55: Activite generatrice revenus | AJ55: Statut entrepreneurial | AK55: Situation economique | AL55: Localite | AM55: Pays | AN55: Departement | AO55: District/Commune | AP55: Arrondissement | AQ55: Quartier/Village | AR55: Adresse / zone | AS55: Zone d'intervention | AT55: Telephone principal | AU55: Telephone secondaire | AV55: E-mail | AW55: Contact urgence (nom) | AX55: Telephone contact urgence | AY55: ID projet | AZ55: Nom du projet | BA55: Domaine d'intervention | BB55: Date integration projet | BC55: Statut ds le projet | BD55: Statut du beneficiaire | BE55: Date d'inscription | BF55: Date de sortie | BG55: Motif de sortie | BH55: Consentement obtenu | BI55: Autorisation usage donnees | BJ55: Autorisation photo | BK55: Autorisation communication | BL55: Source information | BM55: Date de collecte | BN55: ID agent | BO55: Nom de l'agent | BP55: Fonction agent | BQ55: Methode de collecte | BR55: Type de document | BS55: N° / reference document | BT55: Document verifie | BU55: Date de verification | BV55: Anciennete (annees) | BW55: Nb activites suivies | BX55: Nb appuis recus | BY55: Alerte doublon | BZ55: Observations
A56: =IF(D56="","","BEN"&TEXT(ROW()-55,"00000")) -> BEN00001 | B56: Individu | D56: MABIALA | E56: Nzoussi | F56: Christel | G56: =TRIM(D56&" "&E56&" "&F56) -> MABIALA Nzoussi Christel | H56: Feminin | I56: 37330 | J56: =IF(I56="","",DATEDIF(I56,TODAY(),"y")) -> 24 | K56: =IF(J56="","",IF(J56<5,"0-4 ans",IF(J56<10,"5-9 ans",IF(J56<15,"10-14 ans",IF(J56<18,"15-17 ans",IF(J56<25,"18-24 ans",IF(J56<35,"25-34 ans",IF(J56<45,"35-44 ans",IF(J56<55,"45-54 ans",IF(J56<65,"55-64 ans","65 ans et plus")))))))))) -> 18-24 ans | L56: Celibataire | V56: Non | AL56: Makélékélé | AM56: =IFERROR(INDEX(PARAMETRES!$B$536:$B$586,MATCH(AL56,PARAMETRES!$J$536:$J$586,0)),"") -> Congo | AN56: =IFERROR(INDEX(PARAMETRES!$D$536:$D$586,MATCH(AL56,PARAMETRES!$J$536:$J$586,0)),"") -> Brazzaville | AO56: =IFERROR(INDEX(PARAMETRES!$F$536:$F$586,MATCH(AL56,PARAMETRES!$J$536:$J$586,0)),"") -> Brazzaville | AP56: =IFERROR(INDEX(PARAMETRES!$G$536:$G$586,MATCH(AL56,PARAMETRES!$J$536:$J$586,0)),"") -> ARR01 | AY56: PROJ0001 | AZ56: Projet d'appui a l'insertion professionnelle des jeunes | BA56: Education | BC56: Actif | BD56: Actif | BE56: 45323 | BH56: Oui | BV56: =IF(BE56="","",DATEDIF(BE56,TODAY(),"y")) -> 2 | BW56: =COUNTIF(tbl_Beneficiaires_Activites[ID Beneficiaire],A56) -> 0 | BX56: =COUNTIF(tbl_Beneficiaires_Appuis[ID Beneficiaire],A56) -> 0 | BY56: =IF(D56="","",IF(COUNTIFS($D$56:$D$115,D56,$F$56:$F$115,F56,$I$56:$I$115,I56)>1,"DOUBLON POSSIBLE","OK")) -> OK
A57: =IF(D57="","","BEN"&TEXT(ROW()-55,"00000")) | G57: =TRIM(D57&" "&E57&" "&F57) | J57: =IF(I57="","",DATEDIF(I57,TODAY(),"y")) | K57: =IF(J57="","",IF(J57<5,"0-4 ans",IF(J57<10,"5-9 ans",IF(J57<15,"10-14 ans",IF(J57<18,"15-17 ans",IF(J57<25,"18-24 ans",IF(J57<35,"25-34 ans",IF(J57<45,"35-44 ans",IF(J57<55,"45-54 ans",IF(J57<65,"55-64 ans","65 ans et plus")))))))))) | AM57: =IFERROR(INDEX(PARAMETRES!$B$536:$B$586,MATCH(AL57,PARAMETRES!$J$536:$J$586,0)),"") | AN57: =IFERROR(INDEX(PARAMETRES!$D$536:$D$586,MATCH(AL57,PARAMETRES!$J$536:$J$586,0)),"") | AO57: =IFERROR(INDEX(PARAMETRES!$F$536:$F$586,MATCH(AL57,PARAMETRES!$J$536:$J$586,0)),"") | AP57: =IFERROR(INDEX(PARAMETRES!$G$536:$G$586,MATCH(AL57,PARAMETRES!$J$536:$J$586,0)),"") | BV57: =IF(BE57="","",DATEDIF(BE57,TODAY(),"y")) | BW57: =COUNTIF(tbl_Beneficiaires_Activites[ID Beneficiaire],A57) -> 40 | BX57: =COUNTIF(tbl_Beneficiaires_Appuis[ID Beneficiaire],A57) -> 40 | BY57: =IF(D57="","",IF(COUNTIFS($D$56:$D$115,D57,$F$56:$F$115,F57,$I$56:$I$115,I57)>1,"DOUBLON POSSIBLE","OK"))
A58: =IF(D58="","","BEN"&TEXT(ROW()-55,"00000")) | G58: =TRIM(D58&" "&E58&" "&F58) | J58: =IF(I58="","",DATEDIF(I58,TODAY(),"y")) | K58: =IF(J58="","",IF(J58<5,"0-4 ans",IF(J58<10,"5-9 ans",IF(J58<15,"10-14 ans",IF(J58<18,"15-17 ans",IF(J58<25,"18-24 ans",IF(J58<35,"25-34 ans",IF(J58<45,"35-44 ans",IF(J58<55,"45-54 ans",IF(J58<65,"55-64 ans","65 ans et plus")))))))))) | AM58: =IFERROR(INDEX(PARAMETRES!$B$536:$B$586,MATCH(AL58,PARAMETRES!$J$536:$J$586,0)),"") | AN58: =IFERROR(INDEX(PARAMETRES!$D$536:$D$586,MATCH(AL58,PARAMETRES!$J$536:$J$586,0)),"") | AO58: =IFERROR(INDEX(PARAMETRES!$F$536:$F$586,MATCH(AL58,PARAMETRES!$J$536:$J$586,0)),"") | AP58: =IFERROR(INDEX(PARAMETRES!$G$536:$G$586,MATCH(AL58,PARAMETRES!$J$536:$J$586,0)),"") | BV58: =IF(BE58="","",DATEDIF(BE58,TODAY(),"y")) | BW58: =COUNTIF(tbl_Beneficiaires_Activites[ID Beneficiaire],A58) -> 40 | BX58: =COUNTIF(tbl_Beneficiaires_Appuis[ID Beneficiaire],A58) -> 40 | BY58: =IF(D58="","",IF(COUNTIFS($D$56:$D$115,D58,$F$56:$F$115,F58,$I$56:$I$115,I58)>1,"DOUBLON POSSIBLE","OK"))
A59: =IF(D59="","","BEN"&TEXT(ROW()-55,"00000")) | G59: =TRIM(D59&" "&E59&" "&F59) | J59: =IF(I59="","",DATEDIF(I59,TODAY(),"y")) | K59: =IF(J59="","",IF(J59<5,"0-4 ans",IF(J59<10,"5-9 ans",IF(J59<15,"10-14 ans",IF(J59<18,"15-17 ans",IF(J59<25,"18-24 ans",IF(J59<35,"25-34 ans",IF(J59<45,"35-44 ans",IF(J59<55,"45-54 ans",IF(J59<65,"55-64 ans","65 ans et plus")))))))))) | AM59: =IFERROR(INDEX(PARAMETRES!$B$536:$B$586,MATCH(AL59,PARAMETRES!$J$536:$J$586,0)),"") | AN59: =IFERROR(INDEX(PARAMETRES!$D$536:$D$586,MATCH(AL59,PARAMETRES!$J$536:$J$586,0)),"") | AO59: =IFERROR(INDEX(PARAMETRES!$F$536:$F$586,MATCH(AL59,PARAMETRES!$J$536:$J$586,0)),"") | AP59: =IFERROR(INDEX(PARAMETRES!$G$536:$G$586,MATCH(AL59,PARAMETRES!$J$536:$J$586,0)),"") | BV59: =IF(BE59="","",DATEDIF(BE59,TODAY(),"y")) | BW59: =COUNTIF(tbl_Beneficiaires_Activites[ID Beneficiaire],A59) -> 40 | BX59: =COUNTIF(tbl_Beneficiaires_Appuis[ID Beneficiaire],A59) -> 40 | BY59: =IF(D59="","",IF(COUNTIFS($D$56:$D$115,D59,$F$56:$F$115,F59,$I$56:$I$115,I59)>1,"DOUBLON POSSIBLE","OK"))
A60: =IF(D60="","","BEN"&TEXT(ROW()-55,"00000")) | G60: =TRIM(D60&" "&E60&" "&F60) | J60: =IF(I60="","",DATEDIF(I60,TODAY(),"y")) | K60: =IF(J60="","",IF(J60<5,"0-4 ans",IF(J60<10,"5-9 ans",IF(J60<15,"10-14 ans",IF(J60<18,"15-17 ans",IF(J60<25,"18-24 ans",IF(J60<35,"25-34 ans",IF(J60<45,"35-44 ans",IF(J60<55,"45-54 ans",IF(J60<65,"55-64 ans","65 ans et plus")))))))))) | AM60: =IFERROR(INDEX(PARAMETRES!$B$536:$B$586,MATCH(AL60,PARAMETRES!$J$536:$J$586,0)),"") | AN60: =IFERROR(INDEX(PARAMETRES!$D$536:$D$586,MATCH(AL60,PARAMETRES!$J$536:$J$586,0)),"") | AO60: =IFERROR(INDEX(PARAMETRES!$F$536:$F$586,MATCH(AL60,PARAMETRES!$J$536:$J$586,0)),"") | AP60: =IFERROR(INDEX(PARAMETRES!$G$536:$G$586,MATCH(AL60,PARAMETRES!$J$536:$J$586,0)),"") | BV60: =IF(BE60="","",DATEDIF(BE60,TODAY(),"y")) | BW60: =COUNTIF(tbl_Beneficiaires_Activites[ID Beneficiaire],A60) -> 40 | BX60: =COUNTIF(tbl_Beneficiaires_Appuis[ID Beneficiaire],A60) -> 40 | BY60: =IF(D60="","",IF(COUNTIFS($D$56:$D$115,D60,$F$56:$F$115,F60,$I$56:$I$115,I60)>1,"DOUBLON POSSIBLE","OK"))
...

Sheet PROJETS
A1: O.N.G BK — GESTION DES PROJETS | Q1: -> ONG | R1: -> BENEFICIAIRES
A2: Derniere mise a jour : voir cellule ci-dessous — Cette feuille alimentera ACTIVITES, PARTENAIRES, DONATEURS, BUDGET, RECETTES/FINANCEMENTS, DEPENSES, RH, SUIVI-EVALUATION, RAPPORTS et TABLEAU DE BORD.
A4: LEGENDE : texte bleu = champ a completer manuellement | texte vert italique = donnee calculee automatiquement | ne pas modifier les colonnes calculees.
A6: SYNTHESE GENERALE DES PROJETS (calcul automatique)
A7: Total projets | B7: En preparation | C7: Soumis | D7: Approuves | E7: En cours | F7: Termines | G7: Suspendus | H7: Budget total approuve (FCFA) | I7: Financements recus (FCFA) | J7: Avancement moyen (%) | K7: Année sélectionnée | L7: Total
A8: =IF($L$7="Total",COUNTIF(A56:A95,"PROJ*"),COUNTIFS(A56:A95,"PROJ*",X56:X95,">="&DATE(VALUE($L$7),1,1),X56:X95,"<"&DATE(VALUE($L$7)+1,1,1))) -> 1 | B8: =IF($L$7="Total",COUNTIFS(A56:A95,"PROJ*",AD56:AD95,"En preparation"),COUNTIFS(A56:A95,"PROJ*",AD56:AD95,"En preparation",X56:X95,">="&DATE(VALUE($L$7),1,1),X56:X95,"<"&DATE(VALUE($L$7)+1,1,1))) -> 0 | C8: =IF($L$7="Total",COUNTIFS(A56:A95,"PROJ*",AD56:AD95,"Soumis"),COUNTIFS(A56:A95,"PROJ*",AD56:AD95,"Soumis",X56:X95,">="&DATE(VALUE($L$7),1,1),X56:X95,"<"&DATE(VALUE($L$7)+1,1,1))) -> 0 | D8: =IF($L$7="Total",COUNTIFS(A56:A95,"PROJ*",AD56:AD95,"Approuve"),COUNTIFS(A56:A95,"PROJ*",AD56:AD95,"Approuve",X56:X95,">="&DATE(VALUE($L$7),1,1),X56:X95,"<"&DATE(VALUE($L$7)+1,1,1))) -> 0 | E8: =IF($L$7="Total",COUNTIFS(A56:A95,"PROJ*",AD56:AD95,"En cours"),COUNTIFS(A56:A95,"PROJ*",AD56:AD95,"En cours",X56:X95,">="&DATE(VALUE($L$7),1,1),X56:X95,"<"&DATE(VALUE($L$7)+1,1,1))) -> 1 | F8: =IF($L$7="Total",COUNTIFS(A56:A95,"PROJ*",AD56:AD95,"Termine"),COUNTIFS(A56:A95,"PROJ*",AD56:AD95,"Termine",X56:X95,">="&DATE(VALUE($L$7),1,1),X56:X95,"<"&DATE(VALUE($L$7)+1,1,1))) -> 0 | G8: =IF($L$7="Total",COUNTIFS(A56:A95,"PROJ*",AD56:AD95,"Suspendu"),COUNTIFS(A56:A95,"PROJ*",AD56:AD95,"Suspendu",X56:X95,">="&DATE(VALUE($L$7),1,1),X56:X95,"<"&DATE(VALUE($L$7)+1,1,1))) -> 0 | H8: =IF($L$7="Total",SUM(AG56:AG95),SUMIFS(AG56:AG95,A56:A95,"PROJ*",X56:X95,">="&DATE(VALUE($L$7),1,1),X56:X95,"<"&DATE(VALUE($L$7)+1,1,1))) -> 11000000 | I8: =IF($L$7="Total",SUMIF(A56:A95,"PROJ*",AH56:AH95),SUMIFS(AH56:AH95,A56:A95,"PROJ*",X56:X95,">="&DATE(VALUE($L$7),1,1),X56:X95,"<"&DATE(VALUE($L$7)+1,1,1))) -> 6000000 | J8: =IF($L$7="Total",IFERROR(AVERAGEIF(A56:A95,"PROJ*",BD56:BD95),0),IFERROR(AVERAGEIFS(BD56:BD95,A56:A95,"PROJ*",X56:X95,">="&DATE(VALUE($L$7),1,1),X56:X95,"<"&DATE(VALUE($L$7)+1,1,1)),0)) -> 0.45
A10: ANALYSES AUTOMATIQUES
A11: Statut du projet | B11: Nb projets | D11: Domaine d'intervention | E11: Nb projets
A12: Actif | B12: =COUNTIFS(tbl_Projets[Statut du projet],A12) -> 0 | D12: Education | E12: =COUNTIFS(tbl_Projets[Domaine d''intervention],D12) -> 1
A13: Actif | B13: =COUNTIFS(tbl_Projets[Statut du projet],A13) -> 0 | D13: Formation professionnelle | E13: =COUNTIFS(tbl_Projets[Domaine d''intervention],D13) -> 0
A14: Actif | B14: =COUNTIFS(tbl_Projets[Statut du projet],A14) -> 0 | D14: Entrepreneuriat | E14: =COUNTIFS(tbl_Projets[Domaine d''intervention],D14) -> 0
A15: Actif | B15: =COUNTIFS(tbl_Projets[Statut du projet],A15) -> 0 | D15: Culture | E15: =COUNTIFS(tbl_Projets[Domaine d''intervention],D15) -> 0
A16: Actif | B16: =COUNTIFS(tbl_Projets[Statut du projet],A16) -> 0 | D16: Environnement | E16: =COUNTIFS(tbl_Projets[Domaine d''intervention],D16) -> 0
A17: Actif | B17: =COUNTIFS(tbl_Projets[Statut du projet],A17) -> 0 | D17: Sante | E17: =COUNTIFS(tbl_Projets[Domaine d''intervention],D17) -> 0
A18: Actif | B18: =COUNTIFS(tbl_Projets[Statut du projet],A18) -> 0 | D18: Genre | E18: =COUNTIFS(tbl_Projets[Domaine d''intervention],D18) -> 0
A19: Actif | B19: =COUNTIFS(tbl_Projets[Statut du projet],A19) -> 0 | D19: Tourisme | E19: =COUNTIFS(tbl_Projets[Domaine d''intervention],D19) -> 0
A20: Actif | B20: =COUNTIFS(tbl_Projets[Statut du projet],A20) -> 0 | D20: Sport | E20: =COUNTIFS(tbl_Projets[Domaine d''intervention],D20) -> 0
A21: Actif | B21: =COUNTIFS(tbl_Projets[Statut du projet],A21) -> 0 | D21: Agriculture et developpement rural | E21: =COUNTIFS(tbl_Projets[Domaine d''intervention],D21) -> 0
A22: Actif | B22: =COUNTIFS(tbl_Projets[Statut du projet],A22) -> 0 | D22: Elevage | E22: =COUNTIFS(tbl_Projets[Domaine d''intervention],D22) -> 0
A23: Actif | B23: =COUNTIFS(tbl_Projets[Statut du projet],A23) -> 0 | D23: Peche et aquaculture | E23: =COUNTIFS(tbl_Projets[Domaine d''intervention],D23) -> 0
... A26: Actif | B26: =COUNTIFS(tbl_Projets[Statut du projet],A26) -> 0 | D26: Protection sociale | E26: =COUNTIFS(tbl_Projets[Domaine d''intervention],D26) -> 0
D27: Protection de l'enfance | E27: =COUNTIFS(tbl_Projets[Domaine d''intervention],D27) -> 0
D28: Jeunesse | E28: =COUNTIFS(tbl_Projets[Domaine d''intervention],D28) -> 0
D29: Autonomisation des femmes | E29: =COUNTIFS(tbl_Projets[Domaine d''intervention],D29) -> 0
D30: Developpement communautaire | E30: =COUNTIFS(tbl_Projets[Domaine d''intervention],D30) -> 0
D31: Inclusion sociale | E31: =COUNTIFS(tbl_Projets[Domaine d''intervention],D31) -> 0
D32: Handicap et inclusion des personnes vulnerables | E32: =COUNTIFS(tbl_Projets[Domaine d''intervention],D32) -> 0
D33: Emploi et insertion professionnelle | E33: =COUNTIFS(tbl_Projets[Domaine d''intervention],D33) -> 0
D34: Developpement economique local | E34: =COUNTIFS(tbl_Projets[Domaine d''intervention],D34) -> 0
D35: Artisanat | E35: =COUNTIFS(tbl_Projets[Domaine d''intervention],D35) -> 0
D36: Numerique et transformation digitale | E36: =COUNTIFS(tbl_Projets[Domaine d''intervention],D36) -> 0
D37: Technologies et innovation | E37: =COUNTIFS(tbl_Projets[Domaine d''intervention],D37) -> 0
D38: Recherche et developpement | E38: =COUNTIFS(tbl_Projets[Domaine d''intervention],D38) -> 0
