Workbook

Sheet PARAMETRES
A1: O.N.G BK — PARAMETRES DU SYSTEME DE GESTION
A2: Referentiel central du classeur — Donnons la joie a la jeunesse
A4: LEGENDE : cellule grisee = Code (identifiant stable, a ne pas modifier) | cellule blanche = modifiable | colonne Statut = liste deroulante | chaque tableau est extensible : ajoutez vos lignes juste en dessous de la derniere ligne du tableau
A6: SOMMAIRE — cliquez sur un referentiel pour y acceder
A7: 1. ANNEES | I7: 11 element(s)
A8: 2. MOIS | I8: 12 element(s)
A9: 3. TRIMESTRES | I9: 4 element(s)
A10: 4. STATUTS DES PROJETS | I10: 15 element(s)
A11: 5. STATUTS DES ACTIVITES | I11: 9 element(s)
A12: 6. DOMAINES D'INTERVENTION DE L'O.N.G BK | I12: 40 element(s)
A13: 7. TYPES DE PROJETS | I13: 24 element(s)
A14: 8. TYPES D'ACTIVITES | I14: 30 element(s)
A15: 9. CATEGORIES DE BENEFICIAIRES | I15: 29 element(s)
A16: 10. SEXE | I16: 3 element(s)
A17: 11. TRANCHES D'AGE | I17: 11 element(s)
A18: 12. TYPES DE PARTENAIRES | I18: 19 element(s)
... A35: 29. STATUTS GENERAUX | I35: 4 element(s)
A36: -> Nouveaux referentiels ajoutes pour BUDGET : 30. STATUTS BUDGET | 31. TYPES DE BUDGET | 32. SEUILS BUDGETAIRES (voir bas de feuille) | 33. STATUTS RECETTES (voir bas de feuille) | Nouveaux referentiels ajoutes pour RESSOURCES HUMAINES : 34. STATUTS RH | 35. SERVICES/DEPARTEMENTS | 36. NIVEAUX HIERARCHIQUES | 37. TYPES DE CONGE | 38. STATUTS CONGE | 39. NIVEAUX DE COMPETENCE | 40. MOTIFS DE DEPART | 41. FREQUENCES DE PAIEMENT | 42. TYPES DE DOCUMENTS RH | 43. FILTRE ANNEES (voir bas de feuille)
A37: 1. ANNEES
A38: Code | B38: Annee | C38: Statut
A39: AN2024 | B39: 2024 | C39: Actif
A40: AN2025 | B40: 2025 | C40: Actif
A41: AN2026 | B41: 2026 | C41: Actif
A42: AN2027 | B42: 2027 | C42: Actif
A43: AN2028 | B43: 2028 | C43: Actif
A44: AN2029 | B44: 2029 | C44: Actif
A45: AN2030 | B45: 2030 | C45: Actif
A46: AN2031 | B46: 2031 | C46: Actif
A47: AN2032 | B47: 2032 | C47: Actif
A48: AN2033 | B48: 2033 | C48: Actif
A51: 2. MOIS
A52: N° | B52: Mois | C52: Trimestre
A53: 1 | B53: Janvier | C53: T1
A54: 2 | B54: Fevrier | C54: T1
A55: 3 | B55: Mars | C55: T1
A56: 4 | B56: Avril | C56: T2
A57: 5 | B57: Mai | C57: T2
A58: 6 | B58: Juin | C58: T2
A59: 7 | B59: Juillet | C59: T3
A60: 8 | B60: Aout | C60: T3
...

Sheet ONG
A1: O.N.G BK — FICHE D'IDENTIFICATION ET D'INFORMATIONS INSTITUTIONNELLES
A2: Referentiel institutionnel du classeur — Donnons la joie a la jeunesse
A3: Date de derniere mise a jour : | D3: Annee de reference : | F3: Statut de l'organisation : | G3: Actif
A5: LEGENDE : texte bleu = champ a completer par l'ONG | texte vert italique = recupere automatiquement depuis PARAMETRES (ou une future feuille) | valeur grisee en indicateur = sera calculee automatiquement des la creation de la feuille source correspondante
A7: SOMMAIRE — cliquez sur une section pour y acceder
A8: 1. IDENTITE DE L'ONG | G8: fiche
A9: 2. INFORMATIONS JURIDIQUES | G9: fiche
A10: 3. SIEGE ET LOCALISATION | G10: fiche
A11: 4. CONTACTS OFFICIELS | G11: tableau
A12: 5. VISION | G12: zone de texte
A13: 6. MISSION | G13: zone de texte
A14: 7. VALEURS | G14: tableau
A15: 8. OBJECTIFS STRATEGIQUES | G15: tableau
A16: 9. DOMAINES D'INTERVENTION | G16: tableau
A17: 10. ZONES D'INTERVENTION | G17: tableau
A18: 11. ORGANISATION INTERNE | G18: tableau
A19: 12. EFFECTIF GLOBAL | G19: indicateurs
... A30: 23. HISTORIQUE DES MODIFICATIONS | G30: tableau
A32: 1. IDENTITE DE L'ONG
A33: Nom officiel de l'ONG | C33: O.N.G BK
A34: Sigle | C34: BK O.N.G
A35: Nom court | C35: BK
A36: Type d'organisation
A37: Statut juridique
A38: Date de creation
A39: Date de reconnaissance officielle
A40: Numero d'enregistrement
A41: Numero d'agrement
A42: Numero d'identification fiscale (si applicable)
A43: Pays d'enregistrement | C43: Congo
A44: Annee de creation
A45: Devise / slogan | C45: Donnons la joie a la jeunesse
A46: Site internet
A47: Adresse e-mail officielle
A48: Telephone officiel
A49: Adresse physique
A50: Adresse postale
A51: ↑ Retour au sommaire
A53: 2. INFORMATIONS JURIDIQUES
A54: Forme juridique
...

Sheet BENEFICIAIRES
A1: O.N.G BK — BASE DE DONNEES DES BENEFICIAIRES | Q1: -> ONG
A2: Annee de reference : | D2: 2026 | F2: Derniere mise a jour : | I2: =TODAY() -> 46266 | K2: Nombre total de beneficiaires : | O2: =COUNTIF(tbl_Beneficiaires[ID Beneficiaire],"BEN*") -> 1 | Q2: -> PARAMETRES
A4: LEGENDE : texte bleu = champ a completer manuellement | texte vert italique = donnee calculee automatiquement | ne pas modifier les colonnes calculees.
A6: SYNTHESE GENERALE (calcul automatique)
A7: Total beneficiaires | B7: Hommes | C7: Femmes | D7: Autres / non precise | E7: Enfants (0-17 ans) | F7: Jeunes (18-24 ans) | G7: Adultes (25-64 ans) | H7: Personnes agees (65+) | I7: Personnes handicap | J7: Menages distincts | K7: Actifs | L7: Sortis du programme | M7: Année sélectionnée | N7: Total
A8: =IF($N$7="Total",COUNTIF(A56:A115,"BEN*"),COUNTIFS(A56:A115,"BEN*",BB56:BB115,">="&DATE(VALUE($N$7),1,1),BB56:BB115,"<"&DATE(VALUE($N$7)+1,1,1))) -> 1 | B8: =IF($N$7="Total",COUNTIFS(A56:A115,"BEN*",H56:H115,"Masculin"),COUNTIFS(A56:A115,"BEN*",H56:H115,"Masculin",BB56:BB115,">="&DATE(VALUE($N$7),1,1),BB56:BB115,"<"&DATE(VALUE($N$7)+1,1,1))) -> 0 | C8: =IF($N$7="Total",COUNTIFS(A56:A115,"BEN*",H56:H115,"Feminin"),COUNTIFS(A56:A115,"BEN*",H56:H115,"Feminin",BB56:BB115,">="&DATE(VALUE($N$7),1,1),BB56:BB115,"<"&DATE(VALUE($N$7)+1,1,1))) -> 1 | D8: =IF($N$7="Total",COUNTIFS(A56:A115,"BEN*",H56:H115,"Non precise"),COUNTIFS(A56:A115,"BEN*",H56:H115,"Non precise",BB56:BB115,">="&DATE(VALUE($N$7),1,1),BB56:BB115,"<"&DATE(VALUE($N$7)+1,1,1))) -> 0 | E8: =IF($N$7="Total",COUNTIFS(A56:A115,"BEN*",J56:J115,"<18"),COUNTIFS(A56:A115,"BEN*",J56:J115,"<18",BB56:BB115,">="&DATE(VALUE($N$7),1,1),BB56:BB115,"<"&DATE(VALUE($N$7)+1,1,1))) -> 0 | F8: =IF($N$7="Total",COUNTIFS(A56:A115,"BEN*",J56:J115,">=18",J56:J115,"<=24"),COUNTIFS(A56:A115,"BEN*",J56:J115,">=18",J56:J115,"<=24",BB56:BB115,">="&DATE(VALUE($N$7),1,1),BB56:BB115,"<"&DATE(VALUE($N$7)+1,1,1))) -> 1 | G8: =IF($N$7="Total",COUNTIFS(A56:A115,"BEN*",J56:J115,">=25",J56:J115,"<=64"),COUNTIFS(A56:A115,"BEN*",J56:J115,">=25",J56:J115,"<=64",BB56:BB115,">="&DATE(VALUE($N$7),1,1),BB56:BB115,"<"&DATE(VALUE($N$7)+1,1,1))) -> 0 | H8: =IF($N$7="Total",COUNTIFS(A56:A115,"BEN*",J56:J115,">=65"),COUNTIFS(A56:A115,"BEN*",J56:J115,">=65",BB56:BB115,">="&DATE(VALUE($N$7),1,1),BB56:BB115,"<"&DATE(VALUE($N$7)+1,1,1))) -> 0 | I8: =IF($N$7="Total",COUNTIFS(A56:A115,"BEN*",V56:V115,"Oui"),COUNTIFS(A56:A115,"BEN*",V56:V115,"Oui",BB56:BB115,">="&DATE(VALUE($N$7),1,1),BB56:BB115,"<"&DATE(VALUE($N$7)+1,1,1))) -> 0 | J8: =IF($N$7="Total",SUMPRODUCT((N56:N115<>"")/COUNTIF(N56:N115,N56:N115&"")),SUMPRODUCT((N56:N115<>"")*(BB56:BB115>=DATE(VALUE($N$7),1,1))*(BB56:BB115<DATE(VALUE($N$7)+1,1,1))/COUNTIFS(N56:N115,N56:N115,BB56:BB115,">="&DATE(VALUE($N$7),1,1),BB56:BB115,"<"&DATE(VALUE($N$7)+1,1,1)))) -> 0 | K8: =IF($N$7="Total",COUNTIFS(A56:A115,"BEN*",BD56:BD115,"Actif"),COUNTIFS(A56:A115,"BEN*",BD56:BD115,"Actif",BB56:BB115,">="&DATE(VALUE($N$7),1,1),BB56:BB115,"<"&DATE(VALUE($N$7)+1,1,1))) -> 1 | L8: =IF($N$7="Total",COUNTIFS(A56:A115,"BEN*",BD56:BD115,"Sorti du programme"),COUNTIFS(A56:A115,"BEN*",BD56:BD115,"Sorti du programme",BB56:BB115,">="&DATE(VALUE($N$7),1,1),BB56:BB115,"<"&DATE(VALUE($N$7)+1,1,1))) -> 0
A10: ANALYSES AUTOMATIQUES (alimentent le futur TABLEAU DE BORD)
A11: Domaine d'intervention | B11: Nb beneficiaires | D11: Departement | E11: Nb beneficiaires | G11: Projet (nom) | H11: Nb beneficiaires
A12: Education | B12: =COUNTIFS(tbl_Beneficiaires[Domaine d''intervention],A12) -> 1 | D12: Brazzaville | E12: =COUNTIFS(tbl_Beneficiaires[Departement],D12) -> 1 | H12: =IF(G12="","",COUNTIFS(tbl_Beneficiaires[Nom du projet],G12))
A13: Formation professionnelle | B13: =COUNTIFS(tbl_Beneficiaires[Domaine d''intervention],A13) -> 0 | D13: Pointe-Noire | E13: =COUNTIFS(tbl_Beneficiaires[Departement],D13) -> 0 | H13: =IF(G13="","",COUNTIFS(tbl_Beneficiaires[Nom du projet],G13))
A14: Entrepreneuriat | B14: =COUNTIFS(tbl_Beneficiaires[Domaine d''intervention],A14) -> 0 | E14: =IF(D14="","",COUNTIFS(tbl_Beneficiaires[Departement],D14)) | H14: =IF(G14="","",COUNTIFS(tbl_Beneficiaires[Nom du projet],G14))
A15: Culture | B15: =COUNTIFS(tbl_Beneficiaires[Domaine d''intervention],A15) -> 0 | E15: =IF(D15="","",COUNTIFS(tbl_Beneficiaires[Departement],D15)) | H15: =IF(G15="","",COUNTIFS(tbl_Beneficiaires[Nom du projet],G15))
A16: Environnement | B16: =COUNTIFS(tbl_Beneficiaires[Domaine d''intervention],A16) -> 0 | E16: =IF(D16="","",COUNTIFS(tbl_Beneficiaires[Departement],D16)) | H16: =IF(G16="","",COUNTIFS(tbl_Beneficiaires[Nom du projet],G16))
A17: Sante | B17: =COUNTIFS(tbl_Beneficiaires[Domaine d''intervention],A17) -> 0 | E17: =IF(D17="","",COUNTIFS(tbl_Beneficiaires[Departement],D17)) | H17: =IF(G17="","",COUNTIFS(tbl_Beneficiaires[Nom du projet],G17))
A18: Genre | B18: =COUNTIFS(tbl_Beneficiaires[Domaine d''intervention],A18) -> 0 | E18: =IF(D18="","",COUNTIFS(tbl_Beneficiaires[Departement],D18)) | H18: =IF(G18="","",COUNTIFS(tbl_Beneficiaires[Nom du projet],G18))
A19: Tourisme | B19: =COUNTIFS(tbl_Beneficiaires[Domaine d''intervention],A19) -> 0 | E19: =IF(D19="","",COUNTIFS(tbl_Beneficiaires[Departement],D19)) | H19: =IF(G19="","",COUNTIFS(tbl_Beneficiaires[Nom du projet],G19))
A20: Sport | B20: =COUNTIFS(tbl_Beneficiaires[Domaine d''intervention],A20) -> 0 | E20: =IF(D20="","",COUNTIFS(tbl_Beneficiaires[Departement],D20)) | H20: =IF(G20="","",COUNTIFS(tbl_Beneficiaires[Nom du projet],G20))
A21: Agriculture et developpement rural | B21: =COUNTIFS(tbl_Beneficiaires[Domaine d''intervention],A21) -> 0 | E21: =IF(D21="","",COUNTIFS(tbl_Beneficiaires[Departement],D21)) | H21: =IF(G21="","",COUNTIFS(tbl_Beneficiaires[Nom du projet],G21))
A22: Elevage | B22: =COUNTIFS(tbl_Beneficiaires[Domaine d''intervention],A22) -> 0
A23: Peche et aquaculture | B23: =COUNTIFS(tbl_Beneficiaires[Domaine d''intervention],A23) -> 0 | G23: -> saisir un nom de projet par ligne ci-dessus ; a connecter automatiquement des la creation de la feuille PROJETS.
A24: Securite alimentaire et nutrition | B24: =COUNTIFS(tbl_Beneficiaires[Domaine d''intervention],A24) -> 0
A25: Eau, hygiene et assainissement | B25: =COUNTIFS(tbl_Beneficiaires[Domaine d''intervention],A25) -> 0
A26: Protection sociale | B26: =COUNTIFS(tbl_Beneficiaires[Domaine d''intervention],A26) -> 0
A27: Protection de l'enfance | B27: =COUNTIFS(tbl_Beneficiaires[Domaine d''intervention],A27) -> 0
A28: Jeunesse | B28: =COUNTIFS(tbl_Beneficiaires[Domaine d''intervention],A28) -> 0
A29: Autonomisation des femmes | B29: =COUNTIFS(tbl_Beneficiaires[Domaine d''intervention],A29) -> 0
A30: Developpement communautaire | B30: =COUNTIFS(tbl_Beneficiaires[Domaine d''intervention],A30) -> 0
A31: Inclusion sociale | B31: =COUNTIFS(tbl_Beneficiaires[Domaine d''intervention],A31) -> 0
A32: Handicap et inclusion des personnes vulnerables | B32: =COUNTIFS(tbl_Beneficiaires[Domaine d''intervention],A32) -> 0
A33: Emploi et insertion professionnelle | B33: =COUNTIFS(tbl_Beneficiaires[Domaine d''intervention],A33) -> 0
A34: Developpement economique local | B34: =COUNTIFS(tbl_Beneficiaires[Domaine d''intervention],A34) -> 0
A35: Artisanat | B35: =COUNTIFS(tbl_Beneficiaires[Domaine d''intervention],A35) -> 0
... A51: Autre domaine | B51: =COUNTIFS(tbl_Beneficiaires[Domaine d''intervention],A51) -> 0
A54: TABLEAU PRINCIPAL — LISTE DES BENEFICIAIRES
A55: ID Beneficiaire | B55: Type de beneficiaire | C55: Categorie beneficiaire | D55: Nom | E55: Postnom | F55: Prenom | G55: Nom complet | H55: Sexe | I55: Date de naissance | J55: Age | K55: Tranche d'age | L55: Situation matrimoniale | M55: Nationalite | N55: ID menage | O55: Nom du menage | P55: Taille du menage | Q55: Responsable du menage | R55: Nb hommes menage | S55: Nb femmes menage | T55: Nb enfants menage | U55: Nb pers. vulnerables menage | V55: Handicap | W55: Enfant vulnerable | X55: Pers. agee vulnerable | Y55: Femme vulnerable | Z55: Menage vulnerable | AA55: Personne deplacee | AB55: Autre vulnerabilite | AC55: Niveau instruction | AD55: Situation professionnelle | AE55: Profession | AF55: Secteur d'activite | AG55: Statut professionnel | AH55: Niveau de revenu | AI55: Activite generatrice revenus | AJ55: Statut entrepreneurial | AK55: Situation economique | AL55: Localite | AM55: Pays | AN55: Departement | AO55: District/Commune | AP55: Arrondissement | AQ55: Quartier/Village | AR55: Adresse / zone | AS55: Zone d'intervention | AT55: Telephone principal | AU55: Telephone secondaire | AV55: E-mail | AW55: Contact urgence (nom) | AX55: Telephone contact urgence | AY55: ID projet | AZ55: Nom du projet | BA55: Domaine d'intervention | BB55: Date integration projet | BC55: Statut ds le projet | BD55: Statut du beneficiaire | BE55: Date d'inscription | BF55: Date de sortie | BG55: Motif de sortie | BH55: Consentement obtenu | BI55: Autorisation usage donnees | BJ55: Autorisation photo | BK55: Autorisation communication | BL55: Source information | BM55: Date de collecte | BN55: ID agent | BO55: Nom de l'agent | BP55: Fonction agent | BQ55: Methode de collecte | BR55: Type de document | BS55: N° / reference document | BT55: Document verifie | BU55: Date de verification | BV55: Anciennete (annees) | BW55: Nb activites suivies | BX55: Nb appuis recus | BY55: Alerte doublon | BZ55: Observations
A56: =IF(D56="","","BEN"&TEXT(ROW()-55,"00000")) -> BEN00001 | B56: Individu | D56: MABIALA | E56: Nzoussi | F56: Christel | G56: =TRIM(D56&" "&E56&" "&F56) -> MABIALA Nzoussi Christel | H56: Feminin | I56: 37330 | J56: =IF(I56="","",DATEDIF(I56,TODAY(),"y")) -> 24 | K56: =IF(J56="","",IF(J56<5,"0-4 ans",IF(J56<10,"5-9 ans",IF(J56<15,"10-14 ans",IF(J56<18,"15-17 ans",IF(J56<25,"18-24 ans",IF(J56<35,"25-34 ans",IF(J56<45,"35-44 ans",IF(J56<55,"45-54 ans",IF(J56<65,"55-64 ans","65 ans et plus")))))))))) -> 18-24 ans | L56: Celibataire | V56: Non | AL56: Makélékélé | AM56: =IFERROR(INDEX(PARAMETRES!$B$536:$B$586,MATCH(AL56,PARAMETRES!$J$536:$J$586,0)),"") -> Congo | AN56: =IFERROR(INDEX(PARAMETRES!$D$536:$D$586,MATCH(AL56,PARAMETRES!$J$536:$J$586,0)),"") -> Brazzaville | AO56: =IFERROR(INDEX(PARAMETRES!$F$536:$F$586,MATCH(AL56,PARAMETRES!$J$536:$J$586,0)),"") -> Brazzaville | AP56: =IFERROR(INDEX(PARAMETRES!$G$536:$G$586,MATCH(AL56,PARAMETRES!$J$536:$J$586,0)),"") -> ARR01 | AY56: PROJ0001 | AZ56: Projet d'appui a l'insertion professionnelle des jeunes | BA56: Education | BC56: Actif | BD56: Actif | BE56: 45323 | BH56: Oui | BV56: =IF(BE56="","",DATEDIF(BE56,TODAY(),"y")) -> 2 | BW56: =COUNTIF(tbl_Beneficiaires_Activites[ID Beneficiaire],A56) -> 0 | BX56: =COUNTIF(tbl_Beneficiaires_Appuis[ID Beneficiaire],A56) -> 0 | BY56: =IF(D56="","",IF(COUNTIFS($D$56:$D$115,D56,$F$56:$F$115,F56,$I$56:$I$115,I56)>1,"DOUBLON POSSIBLE","OK")) -> OK
A57: =IF(D57="","","BEN"&TEXT(ROW()-55,"00000")) | G57: =TRIM(D57&" "&E57&" "&F57) | J57: =IF(I57="","",DATEDIF(I57,TODAY(),"y")) | K57: =IF(J57="","",IF(J57<5,"0-4 ans",IF(J57<10,"5-9 ans",IF(J57<15,"10-14 ans",IF(J57<18,"15-17 ans",IF(J57<25,"18-24 ans",IF(J57<35,"25-34 ans",IF(J57<45,"35-44 ans",IF(J57<55,"45-54 ans",IF(J57<65,"55-64 ans","65 ans et plus")))))))))) | AM57: =IFERROR(INDEX(PARAMETRES!$B$536:$B$586,MATCH(AL57,PARAMETRES!$J$536:$J$586,0)),"") | AN57: =IFERROR(INDEX(PARAMETRES!$D$536:$D$586,MATCH(AL57,PARAMETRES!$J$536:$J$586,0)),"") | AO57: =IFERROR(INDEX(PARAMETRES!$F$536:$F$586,MATCH(AL57,PARAMETRES!$J$536:$J$586,0)),"") | AP57: =IFERROR(INDEX(PARAMETRES!$G$536:$G$586,MATCH(AL57,PARAMETRES!$J$536:$J$586,0)),"") | BV57: =IF(BE57="","",DATEDIF(BE57,TODAY(),"y")) | BW57: =COUNTIF(tbl_Beneficiaires_Activites[ID Beneficiaire],A57) -> 40 | BX57: =COUNTIF(tbl_Beneficiaires_Appuis[ID Beneficiaire],A57) -> 40 | BY57: =IF(D57="","",IF(COUNTIFS($D$56:$D$115,D57,$F$56:$F$115,F57,$I$56:$I$115,I57)>1,"DOUBLON POSSIBLE","OK"))
A58: =IF(D58="","","BEN"&TEXT(ROW()-55,"00000")) | G58: =TRIM(D58&" "&E58&" "&F58) | J58: =IF(I58="","",DATEDIF(I58,TODAY(),"y")) | K58: =IF(J58="","",IF(J58<5,"0-4 ans",IF(J58<10,"5-9 ans",IF(J58<15,"10-14 ans",IF(J58<18,"15-17 ans",IF(J58<25,"18-24 ans",IF(J58<35,"25-34 ans",IF(J58<45,"35-44 ans",IF(J58<55,"45-54 ans",IF(J58<65,"55-64 ans","65 ans et plus")))))))))) | AM58: =IFERROR(INDEX(PARAMETRES!$B$536:$B$586,MATCH(AL58,PARAMETRES!$J$536:$J$586,0)),"") | AN58: =IFERROR(INDEX(PARAMETRES!$D$536:$D$586,MATCH(AL58,PARAMETRES!$J$536:$J$586,0)),"") | AO58: =IFERROR(INDEX(PARAMETRES!$F$536:$F$586,MATCH(AL58,PARAMETRES!$J$536:$J$586,0)),"") | AP58: =IFERROR(INDEX(PARAMETRES!$G$536:$G$586,MATCH(AL58,PARAMETRES!$J$536:$J$586,0)),"") | BV58: =IF(BE58="","",DATEDIF(BE58,TODAY(),"y")) | BW58: =COUNTIF(tbl_Beneficiaires_Activites[ID Beneficiaire],A58) -> 40 | BX58: =COUNTIF(tbl_Beneficiaires_Appuis[ID Beneficiaire],A58) -> 40 | BY58: =IF(D58="","",IF(COUNTIFS($D$56:$D$115,D58,$F$56:$F$115,F58,$I$56:$I$115,I58)>1,"DOUBLON POSSIBLE","OK"))
A59: =IF(D59="","","BEN"&TEXT(ROW()-55,"00000")) | G59: =TRIM(D59&" "&E59&" "&F59) | J59: =IF(I59="","",DATEDIF(I59,TODAY(),"y")) | K59: =IF(J59="","",IF(J59<5,"0-4 ans",IF(J59<10,"5-9 ans",IF(J59<15,"10-14 ans",IF(J59<18,"15-17 ans",IF(J59<25,"18-24 ans",IF(J59<35,"25-34 ans",IF(J59<45,"35-44 ans",IF(J59<55,"45-54 ans",IF(J59<65,"55-64 ans","65 ans et plus")))))))))) | AM59: =IFERROR(INDEX(PARAMETRES!$B$536:$B$586,MATCH(AL59,PARAMETRES!$J$536:$J$586,0)),"") | AN59: =IFERROR(INDEX(PARAMETRES!$D$536:$D$586,MATCH(AL59,PARAMETRES!$J$536:$J$586,0)),"") | AO59: =IFERROR(INDEX(PARAMETRES!$F$536:$F$586,MATCH(AL59,PARAMETRES!$J$536:$J$586,0)),"") | AP59: =IFERROR(INDEX(PARAMETRES!$G$536:$G$586,MATCH(AL59,PARAMETRES!$J$536:$J$586,0)),"") | BV59: =IF(BE59="","",DATEDIF(BE59,TODAY(),"y")) | BW59: =COUNTIF(tbl_Beneficiaires_Activites[ID Beneficiaire],A59) -> 40 | BX59: =COUNTIF(tbl_Beneficiaires_Appuis[ID Beneficiaire],A59) -> 40 | BY59: =IF(D59="","",IF(COUNTIFS($D$56:$D$115,D59,$F$56:$F$115,F59,$I$56:$I$115,I59)>1,"DOUBLON POSSIBLE","OK"))
A60: =IF(D60="","","BEN"&TEXT(ROW()-55,"00000")) | G60: =TRIM(D60&" "&E60&" "&F60) | J60: =IF(I60="","",DATEDIF(I60,TODAY(),"y")) | K60: =IF(J60="","",IF(J60<5,"0-4 ans",IF(J60<10,"5-9 ans",IF(J60<15,"10-14 ans",IF(J60<18,"15-17 ans",IF(J60<25,"18-24 ans",IF(J60<35,"25-34 ans",IF(J60<45,"35-44 ans",IF(J60<55,"45-54 ans",IF(J60<65,"55-64 ans","65 ans et plus")))))))))) | AM60: =IFERROR(INDEX(PARAMETRES!$B$536:$B$586,MATCH(AL60,PARAMETRES!$J$536:$J$586,0)),"") | AN60: =IFERROR(INDEX(PARAMETRES!$D$536:$D$586,MATCH(AL60,PARAMETRES!$J$536:$J$586,0)),"") | AO60: =IFERROR(INDEX(PARAMETRES!$F$536:$F$586,MATCH(AL60,PARAMETRES!$J$536:$J$586,0)),"") | AP60: =IFERROR(INDEX(PARAMETRES!$G$536:$G$586,MATCH(AL60,PARAMETRES!$J$536:$J$586,0)),"") | BV60: =IF(BE60="","",DATEDIF(BE60,TODAY(),"y")) | BW60: =COUNTIF(tbl_Beneficiaires_Activites[ID Beneficiaire],A60) -> 40 | BX60: =COUNTIF(tbl_Beneficiaires_Appuis[ID Beneficiaire],A60) -> 40 | BY60: =IF(D60="","",IF(COUNTIFS($D$56:$D$115,D60,$F$56:$F$115,F60,$I$56:$I$115,I60)>1,"DOUBLON POSSIBLE","OK"))
...

Sheet PROJETS
A1: O.N.G BK — GESTION DES PROJETS | Q1: -> ONG | R1: -> BENEFICIAIRES
A2: Derniere mise a jour : voir cellule ci-dessous — Cette feuille alimentera ACTIVITES, PARTENAIRES, DONATEURS, BUDGET, RECETTES/FINANCEMENTS, DEPENSES, RH, SUIVI-EVALUATION, RAPPORTS et TABLEAU DE BORD.
A4: LEGENDE : texte bleu = champ a completer manuellement | texte vert italique = donnee calculee automatiquement | ne pas modifier les colonnes calculees.
A6: SYNTHESE GENERALE DES PROJETS (calcul automatique)
A7: Total projets | B7: En preparation | C7: Soumis | D7: Approuves | E7: En cours | F7: Termines | G7: Suspendus | H7: Budget total approuve (FCFA) | I7: Financements recus (FCFA) | J7: Avancement moyen (%) | K7: Année sélectionnée | L7: Total
A8: =IF($L$7="Total",COUNTIF(A56:A95,"PROJ*"),COUNTIFS(A56:A95,"PROJ*",X56:X95,">="&DATE(VALUE($L$7),1,1),X56:X95,"<"&DATE(VALUE($L$7)+1,1,1))) -> 1 | B8: =IF($L$7="Total",COUNTIFS(A56:A95,"PROJ*",AD56:AD95,"En preparation"),COUNTIFS(A56:A95,"PROJ*",AD56:AD95,"En preparation",X56:X95,">="&DATE(VALUE($L$7),1,1),X56:X95,"<"&DATE(VALUE($L$7)+1,1,1))) -> 0 | C8: =IF($L$7="Total",COUNTIFS(A56:A95,"PROJ*",AD56:AD95,"Soumis"),COUNTIFS(A56:A95,"PROJ*",AD56:AD95,"Soumis",X56:X95,">="&DATE(VALUE($L$7),1,1),X56:X95,"<"&DATE(VALUE($L$7)+1,1,1))) -> 0 | D8: =IF($L$7="Total",COUNTIFS(A56:A95,"PROJ*",AD56:AD95,"Approuve"),COUNTIFS(A56:A95,"PROJ*",AD56:AD95,"Approuve",X56:X95,">="&DATE(VALUE($L$7),1,1),X56:X95,"<"&DATE(VALUE($L$7)+1,1,1))) -> 0 | E8: =IF($L$7="Total",COUNTIFS(A56:A95,"PROJ*",AD56:AD95,"En cours"),COUNTIFS(A56:A95,"PROJ*",AD56:AD95,"En cours",X56:X95,">="&DATE(VALUE($L$7),1,1),X56:X95,"<"&DATE(VALUE($L$7)+1,1,1))) -> 1 | F8: =IF($L$7="Total",COUNTIFS(A56:A95,"PROJ*",AD56:AD95,"Termine"),COUNTIFS(A56:A95,"PROJ*",AD56:AD95,"Termine",X56:X95,">="&DATE(VALUE($L$7),1,1),X56:X95,"<"&DATE(VALUE($L$7)+1,1,1))) -> 0 | G8: =IF($L$7="Total",COUNTIFS(A56:A95,"PROJ*",AD56:AD95,"Suspendu"),COUNTIFS(A56:A95,"PROJ*",AD56:AD95,"Suspendu",X56:X95,">="&DATE(VALUE($L$7),1,1),X56:X95,"<"&DATE(VALUE($L$7)+1,1,1))) -> 0 | H8: =IF($L$7="Total",SUM(AG56:AG95),SUMIFS(AG56:AG95,A56:A95,"PROJ*",X56:X95,">="&DATE(VALUE($L$7),1,1),X56:X95,"<"&DATE(VALUE($L$7)+1,1,1))) -> 11000000 | I8: =IF($L$7="Total",SUMIF(A56:A95,"PROJ*",AH56:AH95),SUMIFS(AH56:AH95,A56:A95,"PROJ*",X56:X95,">="&DATE(VALUE($L$7),1,1),X56:X95,"<"&DATE(VALUE($L$7)+1,1,1))) -> 6000000 | J8: =IF($L$7="Total",IFERROR(AVERAGEIF(A56:A95,"PROJ*",BD56:BD95),0),IFERROR(AVERAGEIFS(BD56:BD95,A56:A95,"PROJ*",X56:X95,">="&DATE(VALUE($L$7),1,1),X56:X95,"<"&DATE(VALUE($L$7)+1,1,1)),0)) -> 0.45
A10: ANALYSES AUTOMATIQUES
A11: Statut du projet | B11: Nb projets | D11: Domaine d'intervention | E11: Nb projets
A12: Actif | B12: =COUNTIFS(tbl_Projets[Statut du projet],A12) -> 0 | D12: Education | E12: =COUNTIFS(tbl_Projets[Domaine d''intervention],D12) -> 1
A13: Actif | B13: =COUNTIFS(tbl_Projets[Statut du projet],A13) -> 0 | D13: Formation professionnelle | E13: =COUNTIFS(tbl_Projets[Domaine d''intervention],D13) -> 0
A14: Actif | B14: =COUNTIFS(tbl_Projets[Statut du projet],A14) -> 0 | D14: Entrepreneuriat | E14: =COUNTIFS(tbl_Projets[Domaine d''intervention],D14) -> 0
A15: Actif | B15: =COUNTIFS(tbl_Projets[Statut du projet],A15) -> 0 | D15: Culture | E15: =COUNTIFS(tbl_Projets[Domaine d''intervention],D15) -> 0
A16: Actif | B16: =COUNTIFS(tbl_Projets[Statut du projet],A16) -> 0 | D16: Environnement | E16: =COUNTIFS(tbl_Projets[Domaine d''intervention],D16) -> 0
A17: Actif | B17: =COUNTIFS(tbl_Projets[Statut du projet],A17) -> 0 | D17: Sante | E17: =COUNTIFS(tbl_Projets[Domaine d''intervention],D17) -> 0
A18: Actif | B18: =COUNTIFS(tbl_Projets[Statut du projet],A18) -> 0 | D18: Genre | E18: =COUNTIFS(tbl_Projets[Domaine d''intervention],D18) -> 0
A19: Actif | B19: =COUNTIFS(tbl_Projets[Statut du projet],A19) -> 0 | D19: Tourisme | E19: =COUNTIFS(tbl_Projets[Domaine d''intervention],D19) -> 0
A20: Actif | B20: =COUNTIFS(tbl_Projets[Statut du projet],A20) -> 0 | D20: Sport | E20: =COUNTIFS(tbl_Projets[Domaine d''intervention],D20) -> 0
A21: Actif | B21: =COUNTIFS(tbl_Projets[Statut du projet],A21) -> 0 | D21: Agriculture et developpement rural | E21: =COUNTIFS(tbl_Projets[Domaine d''intervention],D21) -> 0
A22: Actif | B22: =COUNTIFS(tbl_Projets[Statut du projet],A22) -> 0 | D22: Elevage | E22: =COUNTIFS(tbl_Projets[Domaine d''intervention],D22) -> 0
A23: Actif | B23: =COUNTIFS(tbl_Projets[Statut du projet],A23) -> 0 | D23: Peche et aquaculture | E23: =COUNTIFS(tbl_Projets[Domaine d''intervention],D23) -> 0
... A26: Actif | B26: =COUNTIFS(tbl_Projets[Statut du projet],A26) -> 0 | D26: Protection sociale | E26: =COUNTIFS(tbl_Projets[Domaine d''intervention],D26) -> 0
D27: Protection de l'enfance | E27: =COUNTIFS(tbl_Projets[Domaine d''intervention],D27) -> 0
D28: Jeunesse | E28: =COUNTIFS(tbl_Projets[Domaine d''intervention],D28) -> 0
D29: Autonomisation des femmes | E29: =COUNTIFS(tbl_Projets[Domaine d''intervention],D29) -> 0
D30: Developpement communautaire | E30: =COUNTIFS(tbl_Projets[Domaine d''intervention],D30) -> 0
D31: Inclusion sociale | E31: =COUNTIFS(tbl_Projets[Domaine d''intervention],D31) -> 0
D32: Handicap et inclusion des personnes vulnerables | E32: =COUNTIFS(tbl_Projets[Domaine d''intervention],D32) -> 0
D33: Emploi et insertion professionnelle | E33: =COUNTIFS(tbl_Projets[Domaine d''intervention],D33) -> 0
D34: Developpement economique local | E34: =COUNTIFS(tbl_Projets[Domaine d''intervention],D34) -> 0
D35: Artisanat | E35: =COUNTIFS(tbl_Projets[Domaine d''intervention],D35) -> 0
D36: Numerique et transformation digitale | E36: =COUNTIFS(tbl_Projets[Domaine d''intervention],D36) -> 0
D37: Technologies et innovation | E37: =COUNTIFS(tbl_Projets[Domaine d''intervention],D37) -> 0
D38: Recherche et developpement | E38: =COUNTIFS(tbl_Projets[Domaine d''intervention],D38) -> 0
... D51: Autre domaine | E51: =COUNTIFS(tbl_Projets[Domaine d''intervention],D51) -> 0
A54: TABLEAU PRINCIPAL — LISTE DES PROJETS
A55: ID Projet | B55: Code interne | C55: Titre complet du projet | D55: Acronyme | E55: Resume | F55: Contexte | G55: Probleme identifie | H55: Justification | I55: Description intervention | J55: Domaine d'intervention | K55: Type de projet | L55: Objectif general | M55: ID responsable | N55: Nom du responsable | O55: Fonction responsable | P55: Telephone responsable | Q55: Email responsable | R55: Localite | S55: Pays | T55: Departement | U55: District/Commune | V55: Arrondissement | W55: Zone specifique | X55: Date debut prevue | Y55: Date debut reelle | Z55: Date fin prevue | AA55: Date fin reelle | AB55: Duree prevue (j) | AC55: Duree reelle (j) | AD55: Statut du projet | AE55: Niveau de priorite | AF55: Budget demande (FCFA) | AG55: Budget approuve (FCFA) | AH55: Financement recu (FCFA) | AI55: Depenses realisees (FCFA) | AJ55: Budget disponible (FCFA) | AK55: Solde (FCFA) | AL55: Taux execution budgetaire | AM55: Nb beneficiaires prevu | AN55: Nb femmes prevu | AO55: Nb hommes prevu | AP55: Nb jeunes prevu | AQ55: Nb enfants prevu | AR55: Nb menages prevu | AS55: Nb beneficiaires reels | AT55: Nb femmes reelles | AU55: Nb hommes reels | AV55: Nb pers. vulnerables reelles | AW55: Nb pers. handicap reelles | AX55: Nb activites total | AY55: Activites planifiees | AZ55: Activites en cours | BA55: Activites realisees | BB55: Activites annulees | BC55: Taux realisation activites | BD55: Taux d'avancement (%) | BE55: Projet en retard | BF55: Echeance proche (<30j) | BG55: Budget en depassement | BH55: Financement insuffisant | BI55: Observations
A56: =IF(C56="","","PROJ"&TEXT(ROW()-55,"0000")) -> PROJ0001 | B56: BK-EDU-2024-01 | C56: Projet d'appui a l'insertion professionnelle des jeunes | D56: PAIJ | E56: Formation professionnelle et accompagnement de 100 jeunes vers l'emploi. | J56: Education | K56: Projet de formation | L56: Ameliorer l'insertion professionnelle des jeunes de Brazzaville. | N56: Jean MABIALA | O56: Coordinateur de projet | R56: Bacongo | S56: =IFERROR(INDEX(PARAMETRES!$B$536:$B$586,MATCH(R56,PARAMETRES!$J$536:$J$586,0)),"") -> Congo | T56: =IFERROR(INDEX(PARAMETRES!$D$536:$D$586,MATCH(R56,PARAMETRES!$J$536:$J$586,0)),"") -> Brazzaville | U56: =IFERROR(INDEX(PARAMETRES!$F$536:$F$586,MATCH(R56,PARAMETRES!$J$536:$J$586,0)),"") -> Brazzaville | V56: =IFERROR(INDEX(PARAMETRES!$G$536:$G$586,MATCH(R56,PARAMETRES!$J$536:$J$586,0)),"") -> ARR02 | X56: 45292 | Z56: 45657 | AB56: =IF(OR(X56="",Z56=""),"",Z56-X56) -> 365 | AC56: =IF(OR(Y56="",AA56=""),"",AA56-Y56) | AD56: En cours | AE56: Haute | AF56: 12000000 | AG56: 11000000 | AH56: =IF(A56="",0,SUMIF(tbl_Projets_Financements[ID Projet],A56,tbl_Projets_Financements[Montant recu])) -> 6000000 | AI56: 4000000 | AJ56: =IF(AG56="",0,AG56)-IF(AI56="",0,AI56) -> 7000000 | AK56: =AH56-AI56 -> 2000000 | AL56: =IF(OR(AG56="",AG56=0),0,AI56/AG56) -> 0.36363636 | AM56: 100 | AN56: 50 | AO56: 50 | AS56: =IF(A56="",0,COUNTIFS(tbl_Beneficiaires[ID projet],A56)) -> 1 | AT56: =IF(A56="",0,COUNTIFS(tbl_Beneficiaires[ID projet],A56,tbl_Beneficiaires[Sexe],"Feminin")) -> 1 | AU56: =IF(A56="",0,COUNTIFS(tbl_Beneficiaires[ID projet],A56,tbl_Beneficiaires[Sexe],"Masculin")) -> 0 | AV56: =IF(A56="",0,COUNTIFS(tbl_Beneficiaires[ID projet],A56,tbl_Beneficiaires[Menage vulnerable],"Oui")) -> 0 | AW56: =IF(A56="",0,COUNTIFS(tbl_Beneficiaires[ID projet],A56,tbl_Beneficiaires[Handicap],"Oui")) -> 0 | AX56: 10 | AY56: 9 | AZ56: 5 | BA56: 3 | BB56: 1 | BC56: =IF(OR(AX56="",AX56=0),0,BA56/AX56) -> 0.3 | BD56: 0.45 | BE56: =IF(A56="","",IF(AND(Z56<>"",TODAY()>Z56,NOT(OR(AD56="Termine",AD56="Cloture",AD56="Annule",AD56="Non retenu"))),"OUI","NON")) -> OUI | BF56: =IF(A56="","",IF(AND(Z56<>"",(Z56-TODAY())>=0,(Z56-TODAY())<=30,NOT(OR(AD56="Termine",AD56="Cloture",AD56="Annule",AD56="Non retenu"))),"OUI","NON")) -> NON | BG56: =IF(A56="","",IF(AI56>AG56,"OUI","NON")) -> NON | BH56: =IF(A56="","",IF(AH56<AG56,"OUI","NON")) -> OUI
A57: =IF(C57="","","PROJ"&TEXT(ROW()-55,"0000")) | S57: =IFERROR(INDEX(PARAMETRES!$B$536:$B$586,MATCH(R57,PARAMETRES!$J$536:$J$586,0)),"") | T57: =IFERROR(INDEX(PARAMETRES!$D$536:$D$586,MATCH(R57,PARAMETRES!$J$536:$J$586,0)),"") | U57: =IFERROR(INDEX(PARAMETRES!$F$536:$F$586,MATCH(R57,PARAMETRES!$J$536:$J$586,0)),"") | V57: =IFERROR(INDEX(PARAMETRES!$G$536:$G$586,MATCH(R57,PARAMETRES!$J$536:$J$586,0)),"") | AB57: =IF(OR(X57="",Z57=""),"",Z57-X57) | AC57: =IF(OR(Y57="",AA57=""),"",AA57-Y57) | AH57: =IF(A57="",0,SUMIF(tbl_Projets_Financements[ID Projet],A57,tbl_Projets_Financements[Montant recu])) -> 0 | AJ57: =IF(AG57="",0,AG57)-IF(AI57="",0,AI57) -> 0 | AK57: =AH57-AI57 -> 0 | AL57: =IF(OR(AG57="",AG57=0),0,AI57/AG57) -> 0 | AS57: =IF(A57="",0,COUNTIFS(tbl_Beneficiaires[ID projet],A57)) -> 0 | AT57: =IF(A57="",0,COUNTIFS(tbl_Beneficiaires[ID projet],A57,tbl_Beneficiaires[Sexe],"Feminin")) -> 0 | AU57: =IF(A57="",0,COUNTIFS(tbl_Beneficiaires[ID projet],A57,tbl_Beneficiaires[Sexe],"Masculin")) -> 0 | AV57: =IF(A57="",0,COUNTIFS(tbl_Beneficiaires[ID projet],A57,tbl_Beneficiaires[Menage vulnerable],"Oui")) -> 0 | AW57: =IF(A57="",0,COUNTIFS(tbl_Beneficiaires[ID projet],A57,tbl_Beneficiaires[Handicap],"Oui")) -> 0 | BC57: =IF(OR(AX57="",AX57=0),0,BA57/AX57) -> 0 | BE57: =IF(A57="","",IF(AND(Z57<>"",TODAY()>Z57,NOT(OR(AD57="Termine",AD57="Cloture",AD57="Annule",AD57="Non retenu"))),"OUI","NON")) | BF57: =IF(A57="","",IF(AND(Z57<>"",(Z57-TODAY())>=0,(Z57-TODAY())<=30,NOT(OR(AD57="Termine",AD57="Cloture",AD57="Annule",AD57="Non retenu"))),"OUI","NON")) | BG57: =IF(A57="","",IF(AI57>AG57,"OUI","NON")) | BH57: =IF(A57="","",IF(AH57<AG57,"OUI","NON"))
A58: =IF(C58="","","PROJ"&TEXT(ROW()-55,"0000")) | S58: =IFERROR(INDEX(PARAMETRES!$B$536:$B$586,MATCH(R58,PARAMETRES!$J$536:$J$586,0)),"") | T58: =IFERROR(INDEX(PARAMETRES!$D$536:$D$586,MATCH(R58,PARAMETRES!$J$536:$J$586,0)),"") | U58: =IFERROR(INDEX(PARAMETRES!$F$536:$F$586,MATCH(R58,PARAMETRES!$J$536:$J$586,0)),"") | V58: =IFERROR(INDEX(PARAMETRES!$G$536:$G$586,MATCH(R58,PARAMETRES!$J$536:$J$586,0)),"") | AB58: =IF(OR(X58="",Z58=""),"",Z58-X58) | AC58: =IF(OR(Y58="",AA58=""),"",AA58-Y58) | AH58: =IF(A58="",0,SUMIF(tbl_Projets_Financements[ID Projet],A58,tbl_Projets_Financements[Montant recu])) -> 0 | AJ58: =IF(AG58="",0,AG58)-IF(AI58="",0,AI58) -> 0 | AK58: =AH58-AI58 -> 0 | AL58: =IF(OR(AG58="",AG58=0),0,AI58/AG58) -> 0 | AS58: =IF(A58="",0,COUNTIFS(tbl_Beneficiaires[ID projet],A58)) -> 0 | AT58: =IF(A58="",0,COUNTIFS(tbl_Beneficiaires[ID projet],A58,tbl_Beneficiaires[Sexe],"Feminin")) -> 0 | AU58: =IF(A58="",0,COUNTIFS(tbl_Beneficiaires[ID projet],A58,tbl_Beneficiaires[Sexe],"Masculin")) -> 0 | AV58: =IF(A58="",0,COUNTIFS(tbl_Beneficiaires[ID projet],A58,tbl_Beneficiaires[Menage vulnerable],"Oui")) -> 0 | AW58: =IF(A58="",0,COUNTIFS(tbl_Beneficiaires[ID projet],A58,tbl_Beneficiaires[Handicap],"Oui")) -> 0 | BC58: =IF(OR(AX58="",AX58=0),0,BA58/AX58) -> 0 | BE58: =IF(A58="","",IF(AND(Z58<>"",TODAY()>Z58,NOT(OR(AD58="Termine",AD58="Cloture",AD58="Annule",AD58="Non retenu"))),"OUI","NON")) | BF58: =IF(A58="","",IF(AND(Z58<>"",(Z58-TODAY())>=0,(Z58-TODAY())<=30,NOT(OR(AD58="Termine",AD58="Cloture",AD58="Annule",AD58="Non retenu"))),"OUI","NON")) | BG58: =IF(A58="","",IF(AI58>AG58,"OUI","NON")) | BH58: =IF(A58="","",IF(AH58<AG58,"OUI","NON"))
A59: =IF(C59="","","PROJ"&TEXT(ROW()-55,"0000")) | S59: =IFERROR(INDEX(PARAMETRES!$B$536:$B$586,MATCH(R59,PARAMETRES!$J$536:$J$586,0)),"") | T59: =IFERROR(INDEX(PARAMETRES!$D$536:$D$586,MATCH(R59,PARAMETRES!$J$536:$J$586,0)),"") | U59: =IFERROR(INDEX(PARAMETRES!$F$536:$F$586,MATCH(R59,PARAMETRES!$J$536:$J$586,0)),"") | V59: =IFERROR(INDEX(PARAMETRES!$G$536:$G$586,MATCH(R59,PARAMETRES!$J$536:$J$586,0)),"") | AB59: =IF(OR(X59="",Z59=""),"",Z59-X59) | AC59: =IF(OR(Y59="",AA59=""),"",AA59-Y59) | AH59: =IF(A59="",0,SUMIF(tbl_Projets_Financements[ID Projet],A59,tbl_Projets_Financements[Montant recu])) -> 0 | AJ59: =IF(AG59="",0,AG59)-IF(AI59="",0,AI59) -> 0 | AK59: =AH59-AI59 -> 0 | AL59: =IF(OR(AG59="",AG59=0),0,AI59/AG59) -> 0 | AS59: =IF(A59="",0,COUNTIFS(tbl_Beneficiaires[ID projet],A59)) -> 0 | AT59: =IF(A59="",0,COUNTIFS(tbl_Beneficiaires[ID projet],A59,tbl_Beneficiaires[Sexe],"Feminin")) -> 0 | AU59: =IF(A59="",0,COUNTIFS(tbl_Beneficiaires[ID projet],A59,tbl_Beneficiaires[Sexe],"Masculin")) -> 0 | AV59: =IF(A59="",0,COUNTIFS(tbl_Beneficiaires[ID projet],A59,tbl_Beneficiaires[Menage vulnerable],"Oui")) -> 0 | AW59: =IF(A59="",0,COUNTIFS(tbl_Beneficiaires[ID projet],A59,tbl_Beneficiaires[Handicap],"Oui")) -> 0 | BC59: =IF(OR(AX59="",AX59=0),0,BA59/AX59) -> 0 | BE59: =IF(A59="","",IF(AND(Z59<>"",TODAY()>Z59,NOT(OR(AD59="Termine",AD59="Cloture",AD59="Annule",AD59="Non retenu"))),"OUI","NON")) | BF59: =IF(A59="","",IF(AND(Z59<>"",(Z59-TODAY())>=0,(Z59-TODAY())<=30,NOT(OR(AD59="Termine",AD59="Cloture",AD59="Annule",AD59="Non retenu"))),"OUI","NON")) | BG59: =IF(A59="","",IF(AI59>AG59,"OUI","NON")) | BH59: =IF(A59="","",IF(AH59<AG59,"OUI","NON"))
...

Sheet ACTIVITES
A1: O.N.G BK — PLANIFICATION ET SUIVI DES ACTIVITES | Q1: -> PROJETS | R1: -> BENEFICIAIRES | S1: -> PARAMETRES
A2: Derniere mise a jour : voir cellule ci-dessous — Cette feuille alimente PROJETS, BENEFICIAIRES, BUDGET, RECETTES/FINANCEMENTS, DEPENSES, RESSOURCES HUMAINES, SUIVI-EVALUATION, RAPPORTS et TABLEAU DE BORD.
A4: LEGENDE : texte bleu = champ a completer manuellement | texte vert italique = donnee calculee automatiquement | ne pas modifier les colonnes calculees.
A6: SYNTHESE GENERALE DES ACTIVITES (calcul automatique)
A7: Total activites | B7: Planifiees | C7: En cours | D7: Realisees | E7: Reportees | F7: Annulees | G7: Taux global de realisation | H7: Nb projets concernes | I7: Total | J7: Total
A8: =COUNTIF(A56:A105,"ACT*") -> 1 | B8: =IF($I$7="Total",COUNTIFS(A56:A105,"ACT*",Z56:Z105,"Planifiee"),COUNTIFS(A56:A105,"ACT*",Z56:Z105,"Planifiee",S56:S105,$I$7)) -> 0 | C8: =IF($I$7="Total",COUNTIFS(A56:A105,"ACT*",Z56:Z105,"En cours"),COUNTIFS(A56:A105,"ACT*",Z56:Z105,"En cours",S56:S105,$I$7)) -> 1 | D8: =IF($I$7="Total",COUNTIFS(A56:A105,"ACT*",Z56:Z105,"Realisee"),COUNTIFS(A56:A105,"ACT*",Z56:Z105,"Realisee",S56:S105,$I$7)) -> 0 | E8: =IF($I$7="Total",COUNTIFS(A56:A105,"ACT*",Z56:Z105,"Reportee"),COUNTIFS(A56:A105,"ACT*",Z56:Z105,"Reportee",S56:S105,$I$7)) -> 0 | F8: =IF($I$7="Total",COUNTIFS(A56:A105,"ACT*",Z56:Z105,"Annulee"),COUNTIFS(A56:A105,"ACT*",Z56:Z105,"Annulee",S56:S105,$I$7)) -> 0 | G8: =IFERROR(D8/A8,0) -> 0 | H8: =SUMPRODUCT((C56:C105<>"")/COUNTIF(C56:C105,C56:C105&"")) -> 1
A10: ANALYSES AUTOMATIQUES
A11: Statut de l'activite | B11: Nb activites | D11: Type d'activite | E11: Nb activites | G11: Domaine d'intervention | H11: Nb activites
A12: Planifiee | B12: =COUNTIFS(tbl_Activites[Statut de l''activite],A12) -> 0 | D12: Formation | E12: =COUNTIFS(tbl_Activites[Type d''activite],D12) -> 0 | G12: Education | H12: =COUNTIFS(tbl_Activites[Domaine d''intervention (activite)],G12) -> 0
A13: En preparation | B13: =COUNTIFS(tbl_Activites[Statut de l''activite],A13) -> 0 | D13: Atelier | E13: =COUNTIFS(tbl_Activites[Type d''activite],D13) -> 0 | G13: Formation professionnelle | H13: =COUNTIFS(tbl_Activites[Domaine d''intervention (activite)],G13) -> 0
A14: Validee | B14: =COUNTIFS(tbl_Activites[Statut de l''activite],A14) -> 0 | D14: Seminaire | E14: =COUNTIFS(tbl_Activites[Type d''activite],D14) -> 0 | G14: Entrepreneuriat | H14: =COUNTIFS(tbl_Activites[Domaine d''intervention (activite)],G14) -> 0
A15: En cours | B15: =COUNTIFS(tbl_Activites[Statut de l''activite],A15) -> 1 | D15: Conference | E15: =COUNTIFS(tbl_Activites[Type d''activite],D15) -> 0 | G15: Culture | H15: =COUNTIFS(tbl_Activites[Domaine d''intervention (activite)],G15) -> 0
A16: Realisee | B16: =COUNTIFS(tbl_Activites[Statut de l''activite],A16) -> 0 | D16: Sensibilisation | E16: =COUNTIFS(tbl_Activites[Type d''activite],D16) -> 0 | G16: Environnement | H16: =COUNTIFS(tbl_Activites[Domaine d''intervention (activite)],G16) -> 0
A17: Partiellement realisee | B17: =COUNTIFS(tbl_Activites[Statut de l''activite],A17) -> 0 | D17: Campagne | E17: =COUNTIFS(tbl_Activites[Type d''activite],D17) -> 0 | G17: Sante | H17: =COUNTIFS(tbl_Activites[Domaine d''intervention (activite)],G17) -> 0
A18: Reportee | B18: =COUNTIFS(tbl_Activites[Statut de l''activite],A18) -> 0 | D18: Coaching | E18: =COUNTIFS(tbl_Activites[Type d''activite],D18) -> 0 | G18: Genre | H18: =COUNTIFS(tbl_Activites[Domaine d''intervention (activite)],G18) -> 0
A19: Suspendue | B19: =COUNTIFS(tbl_Activites[Statut de l''activite],A19) -> 0 | D19: Accompagnement | E19: =COUNTIFS(tbl_Activites[Type d''activite],D19) -> 0 | G19: Tourisme | H19: =COUNTIFS(tbl_Activites[Domaine d''intervention (activite)],G19) -> 0
A20: Annulee | B20: =COUNTIFS(tbl_Activites[Statut de l''activite],A20) -> 0 | D20: Distribution | E20: =COUNTIFS(tbl_Activites[Type d''activite],D20) -> 0 | G20: Sport | H20: =COUNTIFS(tbl_Activites[Domaine d''intervention (activite)],G20) -> 0
D21: Consultation | E21: =COUNTIFS(tbl_Activites[Type d''activite],D21) -> 0 | G21: Agriculture et developpement rural | H21: =COUNTIFS(tbl_Activites[Domaine d''intervention (activite)],G21) -> 0
D22: Enquete | E22: =COUNTIFS(tbl_Activites[Type d''activite],D22) -> 0 | G22: Elevage | H22: =COUNTIFS(tbl_Activites[Domaine d''intervention (activite)],G22) -> 0
D23: Etude | E23: =COUNTIFS(tbl_Activites[Type d''activite],D23) -> 0 | G23: Peche et aquaculture | H23: =COUNTIFS(tbl_Activites[Domaine d''intervention (activite)],G23) -> 0
D24: Recherche | E24: =COUNTIFS(tbl_Activites[Type d''activite],D24) -> 0 | G24: Securite alimentaire et nutrition | H24: =COUNTIFS(tbl_Activites[Domaine d''intervention (activite)],G24) -> 0
D25: Mission terrain | E25: =COUNTIFS(tbl_Activites[Type d''activite],D25) -> 0 | G25: Eau, hygiene et assainissement | H25: =COUNTIFS(tbl_Activites[Domaine d''intervention (activite)],G25) -> 0
D26: Visite | E26: =COUNTIFS(tbl_Activites[Type d''activite],D26) -> 0 | G26: Protection sociale | H26: =COUNTIFS(tbl_Activites[Domaine d''intervention (activite)],G26) -> 0
D27: Reunion | E27: =COUNTIFS(tbl_Activites[Type d''activite],D27) -> 0 | G27: Protection de l'enfance | H27: =COUNTIFS(tbl_Activites[Domaine d''intervention (activite)],G27) -> 0
D28: Forum | E28: =COUNTIFS(tbl_Activites[Type d''activite],D28) -> 0 | G28: Jeunesse | H28: =COUNTIFS(tbl_Activites[Domaine d''intervention (activite)],G28) -> 0
D29: Concours | E29: =COUNTIFS(tbl_Activites[Type d''activite],D29) -> 0 | G29: Autonomisation des femmes | H29: =COUNTIFS(tbl_Activites[Domaine d''intervention (activite)],G29) -> 0
D30: Competition sportive | E30: =COUNTIFS(tbl_Activites[Type d''activite],D30) -> 0 | G30: Developpement communautaire | H30: =COUNTIFS(tbl_Activites[Domaine d''intervention (activite)],G30) -> 0
D31: Evenement culturel | E31: =COUNTIFS(tbl_Activites[Type d''activite],D31) -> 0 | G31: Inclusion sociale | H31: =COUNTIFS(tbl_Activites[Domaine d''intervention (activite)],G31) -> 0
D32: Exposition | E32: =COUNTIFS(tbl_Activites[Type d''activite],D32) -> 0 | G32: Handicap et inclusion des personnes vulnerables | H32: =COUNTIFS(tbl_Activites[Domaine d''intervention (activite)],G32) -> 0
... D41: Autre | E41: =COUNTIFS(tbl_Activites[Type d''activite],D41) -> 0 | G41: Paix, cohesion sociale et prevention des conflits | H41: =COUNTIFS(tbl_Activites[Domaine d''intervention (activite)],G41) -> 0
G42: Action humanitaire et gestion des urgences | H42: =COUNTIFS(tbl_Activites[Domaine d''intervention (activite)],G42) -> 0
G43: Climat et resilience | H43: =COUNTIFS(tbl_Activites[Domaine d''intervention (activite)],G43) -> 0
G44: Gestion durable des ressources naturelles | H44: =COUNTIFS(tbl_Activites[Domaine d''intervention (activite)],G44) -> 0
G45: Biodiversite et conservation | H45: =COUNTIFS(tbl_Activites[Domaine d''intervention (activite)],G45) -> 0
G46: Infrastructures et equipements communautaires | H46: =COUNTIFS(tbl_Activites[Domaine d''intervention (activite)],G46) -> 0
G47: Developpement urbain et territorial | H47: =COUNTIFS(tbl_Activites[Domaine d''intervention (activite)],G47) -> 0
G48: Communication et information | H48: =COUNTIFS(tbl_Activites[Domaine d''intervention (activite)],G48) -> 0
G49: Mobilite et echanges culturels | H49: =COUNTIFS(tbl_Activites[Domaine d''intervention (activite)],G49) -> 0
G50: Patrimoine et tourisme culturel | H50: =COUNTIFS(tbl_Activites[Domaine d''intervention (activite)],G50) -> 0
G51: Autre domaine | H51: =COUNTIFS(tbl_Activites[Domaine d''intervention (activite)],G51) -> 0
...

Sheet PARTENAIRES
A1: O.N.G BK — GESTION DES PARTENAIRES | Q1: -> PROJETS | R1: -> ACTIVITES | S1: -> PARAMETRES
A2: Derniere mise a jour : voir cellule ci-dessous — Cette feuille alimente PROJETS, ACTIVITES, DONATEURS, RECETTES/FINANCEMENTS, DEPENSES, RESSOURCES HUMAINES, SUIVI-EVALUATION, RAPPORTS et TABLEAU DE BORD.
A4: LEGENDE : texte bleu = champ a completer manuellement | texte vert italique = donnee calculee automatiquement | ne pas modifier les colonnes calculees | cellule grisee = calcul automatique.
A6: SYNTHESE GENERALE DES PARTENAIRES (calcul automatique)
A7: Total partenaires | B7: Actifs | C7: Prospects | D7: Inactifs | E7: Techniques | F7: Financiers | G7: Institutionnels | H7: Conventions actives | I7: Conventions a renouveler (<=60j)
A8: =COUNTIF(C56:C115,"<>") -> 0 | B8: =COUNTIF(AN56:AN115,"Actif")+COUNTIF(AN56:AN115,"En partenariat") -> 0 | C8: =COUNTIF(AN56:AN115,"Prospect") -> 0 | D8: =COUNTIF(AN56:AN115,"Inactif") -> 0 | E8: =COUNTIF(F56:F115,"Partenaire technique") -> 0 | F8: =COUNTIF(F56:F115,"Partenaire financier") -> 0 | G8: =COUNTIF(F56:F115,"Partenaire institutionnel") -> 0 | H8: =COUNTIF(tbl_Partenaires_Conventions[Statut],"Active") -> 0 | I8: =COUNTIFS(tbl_Partenaires_Conventions[Statut],"Active",tbl_Partenaires_Conventions[Date fin],"<="&(TODAY()+60)) -> 0
A10: ANALYSES AUTOMATIQUES
A11: Statut du partenaire | B11: Nb partenaires | D11: Type de partenaire | E11: Nb partenaires | G11: Domaine de collaboration | H11: Nb partenaires
A12: Prospect | B12: =COUNTIF(tbl_Partenaires[Statut du partenaire],A12) -> 0 | D12: Partenaire financier | E12: =COUNTIF(tbl_Partenaires[Type de partenaire],D12) -> 0 | G12: Education | H12: =COUNTIF(tbl_Partenaires[Domaine de collaboration principal],G12) -> 0
A13: En discussion | B13: =COUNTIF(tbl_Partenaires[Statut du partenaire],A13) -> 0 | D13: Partenaire technique | E13: =COUNTIF(tbl_Partenaires[Type de partenaire],D13) -> 0 | G13: Formation professionnelle | H13: =COUNTIF(tbl_Partenaires[Domaine de collaboration principal],G13) -> 0
A14: Actif | B14: =COUNTIF(tbl_Partenaires[Statut du partenaire],A14) -> 0 | D14: Partenaire institutionnel | E14: =COUNTIF(tbl_Partenaires[Type de partenaire],D14) -> 0 | G14: Entrepreneuriat | H14: =COUNTIF(tbl_Partenaires[Domaine de collaboration principal],G14) -> 0
A15: En partenariat | B15: =COUNTIF(tbl_Partenaires[Statut du partenaire],A15) -> 0 | D15: Partenaire gouvernemental | E15: =COUNTIF(tbl_Partenaires[Type de partenaire],D15) -> 0 | G15: Culture | H15: =COUNTIF(tbl_Partenaires[Domaine de collaboration principal],G15) -> 0
A16: Suspendu | B16: =COUNTIF(tbl_Partenaires[Statut du partenaire],A16) -> 0 | D16: Collectivite locale | E16: =COUNTIF(tbl_Partenaires[Type de partenaire],D16) -> 0 | G16: Environnement | H16: =COUNTIF(tbl_Partenaires[Domaine de collaboration principal],G16) -> 0
A17: Inactif | B17: =COUNTIF(tbl_Partenaires[Statut du partenaire],A17) -> 0 | D17: Organisation internationale | E17: =COUNTIF(tbl_Partenaires[Type de partenaire],D17) -> 0 | G17: Sante | H17: =COUNTIF(tbl_Partenaires[Domaine de collaboration principal],G17) -> 0
A18: Termine | B18: =COUNTIF(tbl_Partenaires[Statut du partenaire],A18) -> 0 | D18: ONG nationale | E18: =COUNTIF(tbl_Partenaires[Type de partenaire],D18) -> 0 | G18: Genre | H18: =COUNTIF(tbl_Partenaires[Domaine de collaboration principal],G18) -> 0
A19: A renouveler | B19: =COUNTIF(tbl_Partenaires[Statut du partenaire],A19) -> 0 | D19: ONG internationale | E19: =COUNTIF(tbl_Partenaires[Type de partenaire],D19) -> 0 | G19: Tourisme | H19: =COUNTIF(tbl_Partenaires[Domaine de collaboration principal],G19) -> 0
A20: Autre | B20: =COUNTIF(tbl_Partenaires[Statut du partenaire],A20) -> 0 | D20: Association | E20: =COUNTIF(tbl_Partenaires[Type de partenaire],D20) -> 0 | G20: Sport | H20: =COUNTIF(tbl_Partenaires[Domaine de collaboration principal],G20) -> 0
D21: Entreprise privee | E21: =COUNTIF(tbl_Partenaires[Type de partenaire],D21) -> 0 | G21: Agriculture et developpement rural | H21: =COUNTIF(tbl_Partenaires[Domaine de collaboration principal],G21) -> 0
D22: Fondation | E22: =COUNTIF(tbl_Partenaires[Type de partenaire],D22) -> 0 | G22: Elevage | H22: =COUNTIF(tbl_Partenaires[Domaine de collaboration principal],G22) -> 0
D23: Universite | E23: =COUNTIF(tbl_Partenaires[Type de partenaire],D23) -> 0 | G23: Peche et aquaculture | H23: =COUNTIF(tbl_Partenaires[Domaine de collaboration principal],G23) -> 0
D24: Etablissement scolaire | E24: =COUNTIF(tbl_Partenaires[Type de partenaire],D24) -> 0 | G24: Securite alimentaire et nutrition | H24: =COUNTIF(tbl_Partenaires[Domaine de collaboration principal],G24) -> 0
D25: Centre de recherche | E25: =COUNTIF(tbl_Partenaires[Type de partenaire],D25) -> 0 | G25: Eau, hygiene et assainissement | H25: =COUNTIF(tbl_Partenaires[Domaine de collaboration principal],G25) -> 0
D26: Organisation communautaire | E26: =COUNTIF(tbl_Partenaires[Type de partenaire],D26) -> 0 | G26: Protection sociale | H26: =COUNTIF(tbl_Partenaires[Domaine de collaboration principal],G26) -> 0
D27: Organisation professionnelle | E27: =COUNTIF(tbl_Partenaires[Type de partenaire],D27) -> 0 | G27: Protection de l'enfance | H27: =COUNTIF(tbl_Partenaires[Domaine de collaboration principal],G27) -> 0
D28: Media | E28: =COUNTIF(tbl_Partenaires[Type de partenaire],D28) -> 0 | G28: Jeunesse | H28: =COUNTIF(tbl_Partenaires[Domaine de collaboration principal],G28) -> 0
D29: Institution financiere | E29: =COUNTIF(tbl_Partenaires[Type de partenaire],D29) -> 0 | G29: Autonomisation des femmes | H29: =COUNTIF(tbl_Partenaires[Domaine de collaboration principal],G29) -> 0
D30: Autre | E30: =COUNTIF(tbl_Partenaires[Type de partenaire],D30) -> 0 | G30: Developpement communautaire | H30: =COUNTIF(tbl_Partenaires[Domaine de collaboration principal],G30) -> 0
G31: Inclusion sociale | H31: =COUNTIF(tbl_Partenaires[Domaine de collaboration principal],G31) -> 0
G32: Handicap et inclusion des personnes vulnerables | H32: =COUNTIF(tbl_Partenaires[Domaine de collaboration principal],G32) -> 0
G33: Emploi et insertion professionnelle | H33: =COUNTIF(tbl_Partenaires[Domaine de collaboration principal],G33) -> 0
G34: Developpement economique local | H34: =COUNTIF(tbl_Partenaires[Domaine de collaboration principal],G34) -> 0
G35: Artisanat | H35: =COUNTIF(tbl_Partenaires[Domaine de collaboration principal],G35) -> 0
G36: Numerique et transformation digitale | H36: =COUNTIF(tbl_Partenaires[Domaine de collaboration principal],G36) -> 0
G37: Technologies et innovation | H37: =COUNTIF(tbl_Partenaires[Domaine de collaboration principal],G37) -> 0
G38: Recherche et developpement | H38: =COUNTIF(tbl_Partenaires[Domaine de collaboration principal],G38) -> 0
G39: Gouvernance et citoyennete | H39: =COUNTIF(tbl_Partenaires[Domaine de collaboration principal],G39) -> 0
G40: Droits humains | H40: =COUNTIF(tbl_Partenaires[Domaine de collaboration principal],G40) -> 0
G41: Paix, cohesion sociale et prevention des conflits | H41: =COUNTIF(tbl_Partenaires[Domaine de collaboration principal],G41) -> 0
G42: Action humanitaire et gestion des urgences | H42: =COUNTIF(tbl_Partenaires[Domaine de collaboration principal],G42) -> 0
... G51: Autre domaine | H51: =COUNTIF(tbl_Partenaires[Domaine de collaboration principal],G51) -> 0
...

Sheet DONATEURS
A1: O.N.G BK — GESTION DES DONATEURS & OPPORTUNITES DE FINANCEMENT | Q1: -> PROJETS | R1: -> PARTENAIRES | S1: -> PARAMETRES
A2: Derniere mise a jour : voir cellule ci-dessous — Cette feuille est alimentee par PARTENAIRES et alimente PROJETS, BUDGET, RECETTES/FINANCEMENTS, DEPENSES, SUIVI-EVALUATION, RAPPORTS et TABLEAU DE BORD.
A4: LEGENDE : texte bleu = champ a completer manuellement | texte vert italique = donnee calculee automatiquement | ne pas modifier les colonnes calculees | cellule grisee = calcul automatique.
A6: SYNTHESE GENERALE DES DONATEURS (calcul automatique)
A7: Total donateurs | B7: Actifs | C7: Potentiels (prospects) | D7: Nb opportunites | E7: Opportunites ouvertes | F7: Demandes soumises | G7: Financements obtenus | H7: Montant total demande (FCFA) | I7: Montant total obtenu (FCFA) | J7: Taux de reussite (%)
A8: =COUNTIF(B56:B205,"<>") -> 1 | B8: =COUNTIF(AB56:AB205,"Actif")+COUNTIF(AB56:AB205,"Financement obtenu") -> 1 | C8: =COUNTIF(AB56:AB205,"Prospect") -> 0 | D8: =COUNTIF(tbl_Donateurs_Opportunites[ID Donateur],"<>") -> 0 | E8: =COUNTIF(tbl_Donateurs_Opportunites[Statut],"Ouverte") -> 0 | F8: =COUNTIFS(tbl_Donateurs_Demandes[Statut],"<>A preparer",tbl_Donateurs_Demandes[Statut],"<>En preparation") -> 60 | G8: =COUNTIF(tbl_Donateurs_Demandes[Statut],"Approuvee")+COUNTIF(tbl_Donateurs_Demandes[Statut],"Financement recu") -> 0 | H8: =SUM(tbl_Donateurs_Demandes[Montant demande]) -> 0 | I8: =SUM(tbl_Donateurs_Demandes[Montant accorde]) -> 0 | J8: =IFERROR(G8/F8,"") -> 0
A10: ANALYSES AUTOMATIQUES
A11: Statut du donateur | B11: Nb donateurs | D11: Type de donateur | E11: Nb donateurs | G11: Domaine finance principal | H11: Nb donateurs
A12: Prospect | B12: =COUNTIF(tbl_Donateurs[Statut du donateur],A12) -> 0 | D12: Gouvernement | E12: =COUNTIF(tbl_Donateurs[Type de donateur],D12) -> 0 | G12: Education | H12: =COUNTIF(tbl_Donateurs[Domaine finance principal],G12) -> 0
A13: Contact etabli | B13: =COUNTIF(tbl_Donateurs[Statut du donateur],A13) -> 0 | D13: Ministere | E13: =COUNTIF(tbl_Donateurs[Type de donateur],D13) -> 0 | G13: Formation professionnelle | H13: =COUNTIF(tbl_Donateurs[Domaine finance principal],G13) -> 0
A14: En discussion | B14: =COUNTIF(tbl_Donateurs[Statut du donateur],A14) -> 0 | D14: Ambassade | E14: =COUNTIF(tbl_Donateurs[Type de donateur],D14) -> 0 | G14: Entrepreneuriat | H14: =COUNTIF(tbl_Donateurs[Domaine finance principal],G14) -> 0
A15: Actif | B15: =COUNTIF(tbl_Donateurs[Statut du donateur],A15) -> 0 | D15: Agence de cooperation | E15: =COUNTIF(tbl_Donateurs[Type de donateur],D15) -> 0 | G15: Culture | H15: =COUNTIF(tbl_Donateurs[Domaine finance principal],G15) -> 0
A16: Financement obtenu | B16: =COUNTIF(tbl_Donateurs[Statut du donateur],A16) -> 1 | D16: Organisation internationale | E16: =COUNTIF(tbl_Donateurs[Type de donateur],D16) -> 0 | G16: Environnement | H16: =COUNTIF(tbl_Donateurs[Domaine finance principal],G16) -> 0
A17: A relancer | B17: =COUNTIF(tbl_Donateurs[Statut du donateur],A17) -> 0 | D17: Fondation | E17: =COUNTIF(tbl_Donateurs[Type de donateur],D17) -> 0 | G17: Sante | H17: =COUNTIF(tbl_Donateurs[Domaine finance principal],G17) -> 0
A18: Inactif | B18: =COUNTIF(tbl_Donateurs[Statut du donateur],A18) -> 0 | D18: Entreprise | E18: =COUNTIF(tbl_Donateurs[Type de donateur],D18) -> 0 | G18: Genre | H18: =COUNTIF(tbl_Donateurs[Domaine finance principal],G18) -> 0
A19: Suspendu | B19: =COUNTIF(tbl_Donateurs[Statut du donateur],A19) -> 0 | D19: Banque | E19: =COUNTIF(tbl_Donateurs[Type de donateur],D19) -> 0 | G19: Tourisme | H19: =COUNTIF(tbl_Donateurs[Domaine finance principal],G19) -> 0
A20: Termine | B20: =COUNTIF(tbl_Donateurs[Statut du donateur],A20) -> 0 | D20: Institution financiere | E20: =COUNTIF(tbl_Donateurs[Type de donateur],D20) -> 0 | G20: Sport | H20: =COUNTIF(tbl_Donateurs[Domaine finance principal],G20) -> 0
D21: ONG | E21: =COUNTIF(tbl_Donateurs[Type de donateur],D21) -> 1 | G21: Agriculture et developpement rural | H21: =COUNTIF(tbl_Donateurs[Domaine finance principal],G21) -> 0
D22: Particulier | E22: =COUNTIF(tbl_Donateurs[Type de donateur],D22) -> 0 | G22: Elevage | H22: =COUNTIF(tbl_Donateurs[Domaine finance principal],G22) -> 0
D23: Mecene | E23: =COUNTIF(tbl_Donateurs[Type de donateur],D23) -> 0 | G23: Peche et aquaculture | H23: =COUNTIF(tbl_Donateurs[Domaine finance principal],G23) -> 0
D24: Autre | E24: =COUNTIF(tbl_Donateurs[Type de donateur],D24) -> 0 | G24: Securite alimentaire et nutrition | H24: =COUNTIF(tbl_Donateurs[Domaine finance principal],G24) -> 0
G25: Eau, hygiene et assainissement | H25: =COUNTIF(tbl_Donateurs[Domaine finance principal],G25) -> 0
G26: Protection sociale | H26: =COUNTIF(tbl_Donateurs[Domaine finance principal],G26) -> 0
G27: Protection de l'enfance | H27: =COUNTIF(tbl_Donateurs[Domaine finance principal],G27) -> 0
G28: Jeunesse | H28: =COUNTIF(tbl_Donateurs[Domaine finance principal],G28) -> 0
G29: Autonomisation des femmes | H29: =COUNTIF(tbl_Donateurs[Domaine finance principal],G29) -> 0
G30: Developpement communautaire | H30: =COUNTIF(tbl_Donateurs[Domaine finance principal],G30) -> 0
G31: Inclusion sociale | H31: =COUNTIF(tbl_Donateurs[Domaine finance principal],G31) -> 0
G32: Handicap et inclusion des personnes vulnerables | H32: =COUNTIF(tbl_Donateurs[Domaine finance principal],G32) -> 0
G33: Emploi et insertion professionnelle | H33: =COUNTIF(tbl_Donateurs[Domaine finance principal],G33) -> 0
G34: Developpement economique local | H34: =COUNTIF(tbl_Donateurs[Domaine finance principal],G34) -> 0
G35: Artisanat | H35: =COUNTIF(tbl_Donateurs[Domaine finance principal],G35) -> 0
G36: Numerique et transformation digitale | H36: =COUNTIF(tbl_Donateurs[Domaine finance principal],G36) -> 0
... G51: Autre domaine | H51: =COUNTIF(tbl_Donateurs[Domaine finance principal],G51) -> 0
A54: TABLEAU PRINCIPAL — LISTE DES DONATEURS
A55: ID Donateur | B55: Nom officiel | C55: Nom court | D55: Sigle | E55: Type de donateur | F55: Categorie de financement | G55: Pays | H55: Ville | I55: Site internet | J55: Adresse | K55: Telephone | L55: Email | M55: Description | N55: Nom contact principal | O55: Prenom contact principal | P55: Fonction contact principal | Q55: Telephone contact principal | R55: Email contact principal | S55: WhatsApp contact principal | T55: Pays contact principal | U55: Ville contact principal | V55: Domaine finance principal | W55: Domaine finance secondaire | X55: Localite financee | Y55: Pays finance | Z55: Departement finance | AA55: Commune finance | AB55: Statut du donateur | AC55: Date premiere prise de contact | AD55: Responsable interne | AE55: Dernier contact | AF55: Prochain contact | AG55: Mode de communication | AH55: Statut de la relation | AI55: Nb opportunites | AJ55: Opportunites ouvertes | AK55: Nb demandes | AL55: Nb financements obtenus | AM55: Montant total demande (FCFA) | AN55: Montant total accorde (FCFA) | AO55: Montant total recu (FCFA) | AP55: Taux de reussite (%) | AQ55: Nb contacts secondaires | AR55: Nb documents | AS55: Nb conventions | AT55: Dernier financement (date) | AU55: Financement moyen (FCFA) | AV55: Alerte a relancer | AW55: Doublon potentiel | AX55: Observations
A56: =IF(B56="","","DON"&TEXT(ROW()-55,"00000")) -> DON00001 | B56: AUSP | C56: AUSP | D56: AUSP | E56: ONG | F56: Contribution financiere | G56: Congo | H56: Brazzaville | P56: Consultant | V56: Developpement urbain et territorial | W56: Infrastructures et equipements communautaires | X56: Bacongo | Y56: =IFERROR(INDEX(PARAMETRES!$B$536:$B$586,MATCH(X56,PARAMETRES!$J$536:$J$586,0)),"") -> Congo | Z56: =IFERROR(INDEX(PARAMETRES!$D$536:$D$586,MATCH(X56,PARAMETRES!$J$536:$J$586,0)),"") -> Brazzaville | AA56: =IFERROR(INDEX(PARAMETRES!$F$536:$F$586,MATCH(X56,PARAMETRES!$J$536:$J$586,0)),"") -> Brazzaville | AB56: Financement obtenu | AG56: Courrier | AI56: =IF(A56="",0,COUNTIF(tbl_Donateurs_Opportunites[ID Donateur],A56)) -> 0 | AJ56: =IF(A56="",0,COUNTIFS(tbl_Donateurs_Opportunites[ID Donateur],A56,tbl_Donateurs_Opportunites[Statut],"Ouverte")) -> 0 | AK56: =IF(A56="",0,COUNTIF(tbl_Donateurs_Demandes[ID Donateur],A56)) -> 0 | AL56: =IF(A56="",0,COUNTIFS(tbl_Donateurs_Demandes[ID Donateur],A56,tbl_Donateurs_Demandes[Statut],"Approuvee")+COUNTIFS(tbl_Donateurs_Demandes[ID Donateur],A56,tbl_Donateurs_Demandes[Statut],"Financement recu")) -> 0 | AM56: =IF(A56="",0,SUMIF(tbl_Donateurs_Demandes[ID Donateur],A56,tbl_Donateurs_Demandes[Montant demande])) -> 0 | AN56: =IF(A56="",0,SUMIF(tbl_Donateurs_Demandes[ID Donateur],A56,tbl_Donateurs_Demandes[Montant accorde])) -> 0 | AO56: =IF(A56="",0,SUMIF(tbl_Donateurs_Decaissements[ID Donateur],A56,tbl_Donateurs_Decaissements[Montant recu])) -> 0 | AP56: =IFERROR(AL56/AK56,"") | AQ56: =IF(A56="",0,COUNTIF(tbl_Donateurs_Contacts[ID Donateur],A56)) -> 0 | AR56: =IF(A56="",0,COUNTIF(tbl_Donateurs_Documents[ID Donateur],A56)) -> 0 | AS56: =IF(A56="",0,COUNTIF(tbl_Donateurs_Conventions[ID Donateur],A56)) -> 0 | AT56: 2500000 | AU56: 2000000 | AV56: =IF(A56="","",IF(OR(AB56="A relancer",AND(AF56<>"",AF56<=TODAY())),"OUI","NON")) -> NON | AW56: =IF(B56="","",IF(OR(COUNTIF($B$56:$B$205,B56)>1,AND(D56<>"",COUNTIF($D$56:$D$205,D56)>1),AND(K56<>"",COUNTIF($K$56:$K$205,K56)>1),AND(L56<>"",COUNTIF($L$56:$L$205,L56)>1)),"OUI","NON")) -> NON
A57: =IF(B57="","","DON"&TEXT(ROW()-55,"00000")) | Y57: =IFERROR(INDEX(PARAMETRES!$B$536:$B$586,MATCH(X57,PARAMETRES!$J$536:$J$586,0)),"") | Z57: =IFERROR(INDEX(PARAMETRES!$D$536:$D$586,MATCH(X57,PARAMETRES!$J$536:$J$586,0)),"") | AA57: =IFERROR(INDEX(PARAMETRES!$F$536:$F$586,MATCH(X57,PARAMETRES!$J$536:$J$586,0)),"") | AI57: =IF(A57="",0,COUNTIF(tbl_Donateurs_Opportunites[ID Donateur],A57)) -> 0 | AJ57: =IF(A57="",0,COUNTIFS(tbl_Donateurs_Opportunites[ID Donateur],A57,tbl_Donateurs_Opportunites[Statut],"Ouverte")) -> 0 | AK57: =IF(A57="",0,COUNTIF(tbl_Donateurs_Demandes[ID Donateur],A57)) -> 0 | AL57: =IF(A57="",0,COUNTIFS(tbl_Donateurs_Demandes[ID Donateur],A57,tbl_Donateurs_Demandes[Statut],"Approuvee")+COUNTIFS(tbl_Donateurs_Demandes[ID Donateur],A57,tbl_Donateurs_Demandes[Statut],"Financement recu")) -> 0 | AM57: =IF(A57="",0,SUMIF(tbl_Donateurs_Demandes[ID Donateur],A57,tbl_Donateurs_Demandes[Montant demande])) -> 0 | AN57: =IF(A57="",0,SUMIF(tbl_Donateurs_Demandes[ID Donateur],A57,tbl_Donateurs_Demandes[Montant accorde])) -> 0 | AO57: =IF(A57="",0,SUMIF(tbl_Donateurs_Decaissements[ID Donateur],A57,tbl_Donateurs_Decaissements[Montant recu])) -> 0 | AP57: =IFERROR(AL57/AK57,"") | AQ57: =IF(A57="",0,COUNTIF(tbl_Donateurs_Contacts[ID Donateur],A57)) -> 0 | AR57: =IF(A57="",0,COUNTIF(tbl_Donateurs_Documents[ID Donateur],A57)) -> 0 | AS57: =IF(A57="",0,COUNTIF(tbl_Donateurs_Conventions[ID Donateur],A57)) -> 0 | AT57: =IFERROR(_xlfn.MAXIFS(tbl_Donateurs_Decaissements[Date recue],tbl_Donateurs_Decaissements[ID Donateur],A57),"") -> 0 | AU57: =IFERROR(AN57/AL57,"") | AV57: =IF(A57="","",IF(OR(AB57="A relancer",AND(AF57<>"",AF57<=TODAY())),"OUI","NON")) | AW57: =IF(B57="","",IF(OR(COUNTIF($B$56:$B$205,B57)>1,AND(D57<>"",COUNTIF($D$56:$D$205,D57)>1),AND(K57<>"",COUNTIF($K$56:$K$205,K57)>1),AND(L57<>"",COUNTIF($L$56:$L$205,L57)>1)),"OUI","NON"))
